Workbook

Sheet Sheet 1
A1: ID | B1: PARTICIPANT | C1: VERSION | D1: ATTACK | E1: ARGS | F1: EXTENSION | G1: ILASP
A2: p75_versionA | B2: p75 | C2: A | D2: att(c,b). att(d,b). | E2: arg(a). arg(b). arg(c). arg(d). | F2: in(a) out(b) | G2: ="{"&F2&"}, {}, {"&D2&E2&"}" -> {in(a) out(b)}, {}, {att(c,b). att(d,b). arg(a). arg(b). arg(c). arg(d).}
A3: p76_versionA | B3: p76 | C3: A | D3: att(b,a). att(c,b). att(d,b). | E3: arg(a). arg(b). arg(c). arg(d). | F3: in(a) out(b) | G3: ="{"&F3&"}, {}, {"&D3&E3&"}" -> {in(a) out(b)}, {}, {att(b,a). att(c,b). att(d,b). arg(a). arg(b). arg(c). arg(d).}
A4: p77_versionA | B4: p77 | C4: A | D4: att(b,a). att(c,b). att(d,b). | E4: arg(a). arg(b). arg(c). arg(d). | F4: out(b) in(c) in(d) | G4: ="{"&F4&"}, {}, {"&D4&E4&"}" -> {out(b) in(c) in(d)}, {}, {att(b,a). att(c,b). att(d,b). arg(a). arg(b). arg(c). arg(d).}
A5: p78_versionA | B5: p78 | C5: A | D5: att(b,a). att(c,b). att(d,b). | E5: arg(a). arg(b). arg(c). arg(d). | F5: in(a) out(b) | G5: ="{"&F5&"}, {}, {"&D5&E5&"}" -> {in(a) out(b)}, {}, {att(b,a). att(c,b). att(d,b). arg(a). arg(b). arg(c). arg(d).}
A6: p79_versionA | B6: p79 | C6: A | D6: att(a,b). | E6: arg(a). arg(b). arg(c). arg(d). | F6: in(a) out(b) out(c) | G6: ="{"&F6&"}, {}, {"&D6&E6&"}" -> {in(a) out(b) out(c)}, {}, {att(a,b). arg(a). arg(b). arg(c). arg(d).}
A7: p80_versionA | B7: p80 | C7: A | D7: att(a,b). att(c,b). att(c,d). | E7: arg(a). arg(b). arg(c). arg(d). | F7: in(a) in(d) | G7: ="{"&F7&"}, {}, {"&D7&E7&"}" -> {in(a) in(d)}, {}, {att(a,b). att(c,b). att(c,d). arg(a). arg(b). arg(c). arg(d).}
A8: p81_versionA | B8: p81 | C8: A | D8: att(b,a). att(c,b). att(d,b). att(d,c). | E8: arg(a). arg(b). arg(c). arg(d). | F8: out(a) in(c) in(d) | G8: ="{"&F8&"}, {}, {"&D8&E8&"}" -> {out(a) in(c) in(d)}, {}, {att(b,a). att(c,b). att(d,b). att(d,c). arg(a). arg(b). arg(c). arg(d).}
A9: p82_versionA | B9: p82 | C9: A | D9: att(b,a). att(c,b). att(d,b). | E9: arg(a). arg(b). arg(c). arg(d). | F9: in(a) out(b) in(c) in(d) | G9: ="{"&F9&"}, {}, {"&D9&E9&"}" -> {in(a) out(b) in(c) in(d)}, {}, {att(b,a). att(c,b). att(d,b). arg(a). arg(b). arg(c). arg(d).}
A10: p83_versionA | B10: p83 | C10: A | D10: att(b,a). att(c,b). att(d,b). att(d,c). | E10: arg(a). arg(b). arg(c). arg(d). | F10: out(b) out(c) in(d) | G10: ="{"&F10&"}, {}, {"&D10&E10&"}" -> {out(b) out(c) in(d)}, {}, {att(b,a). att(c,b). att(d,b). att(d,c). arg(a). arg(b). arg(c). arg(d).}
A11: p84_versionA | B11: p84 | C11: A | D11: att(b,a). att(c,b). att(d,b). att(d,c). | E11: arg(a). arg(b). arg(c). arg(d). | F11: out(b) in(c) in(d) | G11: ="{"&F11&"}, {}, {"&D11&E11&"}" -> {out(b) in(c) in(d)}, {}, {att(b,a). att(c,b). att(d,b). att(d,c). arg(a). arg(b). arg(c). arg(d).}
A12: p85_versionA | B12: p85 | C12: A | D12: att(a,b). att(b,a). att(c,b). att(c,d). att(d,b). att(d,c). | E12: arg(a). arg(b). arg(c). arg(d). | F12: in(a) out(c) | G12: ="{"&F12&"}, {}, {"&D12&E12&"}" -> {in(a) out(c)}, {}, {att(a,b). att(b,a). att(c,b). att(c,d). att(d,b). att(d,c). arg(a). arg(b). arg(c). arg(d).}
A13: p86_versionA | B13: p86 | C13: A | D13: att(b,a). att(c,b). att(d,b). att(d,c). | E13: arg(a). arg(b). arg(c). arg(d). | F13: out(a) in(b) in(d) | G13: ="{"&F13&"}, {}, {"&D13&E13&"}" -> {out(a) in(b) in(d)}, {}, {att(b,a). att(c,b). att(d,b). att(d,c). arg(a). arg(b). arg(c). arg(d).}
... A57: p70_versionC | B57: p70 | C57: C | D57: att(a,b). att(b,c). att(b,d). att(c,b). att(c,d). att(d,b). att(d,c). | E57: arg(a). arg(b). arg(c). arg(d). | F57: in(a) | G57: ="{"&F57&"}, {}, {"&D57&E57&"}" -> {in(a)}, {}, {att(a,b). att(b,c). att(b,d). att(c,b). att(c,d). att(d,b). att(d,c). arg(a). arg(b). arg(c). arg(d).}
A58: p71_versionC | B58: p71 | C58: C | E58: arg(a). arg(b). arg(c). arg(d). | F58: in(a) in(b) out(d) | G58: ="{"&F58&"}, {}, {"&D58&E58&"}" -> {in(a) in(b) out(d)}, {}, {arg(a). arg(b). arg(c). arg(d).}
A59: p72_versionC | B59: p72 | C59: C | D59: att(b,a). att(c,a). att(c,d). att(d,a). att(d,c). | E59: arg(a). arg(b). arg(c). arg(d). | F59: in(a) out(b) in(c) | G59: ="{"&F59&"}, {}, {"&D59&E59&"}" -> {in(a) out(b) in(c)}, {}, {att(b,a). att(c,a). att(c,d). att(d,a). att(d,c). arg(a). arg(b). arg(c). arg(d).}
A60: p73_versionC | B60: p73 | C60: C | D60: att(b,c). att(b,d). att(c,b). att(c,d). att(d,b). att(d,c). | E60: arg(a). arg(b). arg(c). arg(d). | F60: in(a) out(b) | G60: ="{"&F60&"}, {}, {"&D60&E60&"}" -> {in(a) out(b)}, {}, {att(b,c). att(b,d). att(c,b). att(c,d). att(d,b). att(d,c). arg(a). arg(b). arg(c). arg(d).}
A61: p74_versionC | B61: p74 | C61: C | D61: att(b,c). att(c,d). att(d,c). | E61: arg(a). arg(b). arg(c). arg(d). | F61: in(a) in(b) | G61: ="{"&F61&"}, {}, {"&D61&E61&"}" -> {in(a) in(b)}, {}, {att(b,c). att(c,d). att(d,c). arg(a). arg(b). arg(c). arg(d).}
A62: p10_versionD | B62: p10 | C62: D | D62: att(a,b). att(b,a). | E62: arg(a). arg(b). arg(c). | F62: in(b) in(c) | G62: ="{"&F62&"}, {}, {"&D62&E62&"}" -> {in(b) in(c)}, {}, {att(a,b). att(b,a). arg(a). arg(b). arg(c).}
A63: p11_versionD | B63: p11 | C63: D | D63: att(a,b). att(b,a). | E63: arg(a). arg(b). arg(c). | F63: out(a) in(b) | G63: ="{"&F63&"}, {}, {"&D63&E63&"}" -> {out(a) in(b)}, {}, {att(a,b). att(b,a). arg(a). arg(b). arg(c).}
A64: p12_versionD | B64: p12 | C64: D | D64: att(b,a). att(c,b). | E64: arg(a). arg(b). arg(c). | F64: out(a) out(b) in(c) | G64: ="{"&F64&"}, {}, {"&D64&E64&"}" -> {out(a) out(b) in(c)}, {}, {att(b,a). att(c,b). arg(a). arg(b). arg(c).}
A65: p13_versionD | B65: p13 | C65: D | D65: att(b,a). att(c,b). | E65: arg(a). arg(b). arg(c). | F65: in(a) out(b) in(c) | G65: ="{"&F65&"}, {}, {"&D65&E65&"}" -> {in(a) out(b) in(c)}, {}, {att(b,a). att(c,b). arg(a). arg(b). arg(c).}
A66: p14_versionD | B66: p14 | C66: D | D66: att(a,b). att(b,a). att(c,b). | E66: arg(a). arg(b). arg(c). | F66: in(a) out(b) in(c) | G66: ="{"&F66&"}, {}, {"&D66&E66&"}" -> {in(a) out(b) in(c)}, {}, {att(a,b). att(b,a). att(c,b). arg(a). arg(b). arg(c).}
A67: p34_versionD | B67: p34 | C67: D | D67: att(b,a). att(c,b). | E67: arg(a). arg(b). arg(c). | F67: out(a) out(b) in(c) | G67: ="{"&F67&"}, {}, {"&D67&E67&"}" -> {out(a) out(b) in(c)}, {}, {att(b,a). att(c,b). arg(a). arg(b). arg(c).}
A68: p35_versionD | B68: p35 | C68: D | D68: att(b,a). att(c,b). | E68: arg(a). arg(b). arg(c). | F68: out(a) out(b) in(c) | G68: ="{"&F68&"}, {}, {"&D68&E68&"}" -> {out(a) out(b) in(c)}, {}, {att(b,a). att(c,b). arg(a). arg(b). arg(c).}
A69: p36_versionD | B69: p36 | C69: D | D69: att(b,a). att(c,b). | E69: arg(a). arg(b). arg(c). | F69: out(a) out(b) in(c) | G69: ="{"&F69&"}, {}, {"&D69&E69&"}" -> {out(a) out(b) in(c)}, {}, {att(b,a). att(c,b). arg(a). arg(b). arg(c).}
A70: p37_versionD | B70: p37 | C70: D | D70: att(b,a). att(c,b). | E70: arg(a). arg(b). arg(c). | F70: in(b) in(c) | G70: ="{"&F70&"}, {}, {"&D70&E70&"}" -> {in(b) in(c)}, {}, {att(b,a). att(c,b). arg(a). arg(b). arg(c).}
... A87: p29_versionE | B87: p29 | C87: E | D87: att(a,b). att(b,a). att(c,b). | E87: arg(a). arg(b). arg(c). | F87: in(a) out(b) in(c) | G87: ="{"&F87&"}, {}, {"&D87&E87&"}" -> {in(a) out(b) in(c)}, {}, {att(a,b). att(b,a). att(c,b). arg(a). arg(b). arg(c).}
A88: p30_versionE | B88: p30 | C88: E | D88: att(b,a). att(c,b). | E88: arg(a). arg(b). arg(c). | G88: ="{"&F88&"}, {}, {"&D88&E88&"}" -> {}, {}, {att(b,a). att(c,b). arg(a). arg(b). arg(c).}
A89: p31_versionE | B89: p31 | C89: E | D89: att(a,b). att(b,a). att(c,a). att(c,b). | E89: arg(a). arg(b). arg(c). | F89: out(b) in(c) | G89: ="{"&F89&"}, {}, {"&D89&E89&"}" -> {out(b) in(c)}, {}, {att(a,b). att(b,a). att(c,a). att(c,b). arg(a). arg(b). arg(c).}
A90: p32_versionE | B90: p32 | C90: E | D90: att(b,a). att(c,b). | E90: arg(a). arg(b). arg(c). | F90: out(b) in(c) | G90: ="{"&F90&"}, {}, {"&D90&E90&"}" -> {out(b) in(c)}, {}, {att(b,a). att(c,b). arg(a). arg(b). arg(c).}
A91: p33_versionE | B91: p33 | C91: E | D91: att(b,a). att(b,c). att(c,b). | E91: arg(a). arg(b). arg(c). | F91: out(b) in(c) | G91: ="{"&F91&"}, {}, {"&D91&E91&"}" -> {out(b) in(c)}, {}, {att(b,a). att(b,c). att(c,b). arg(a). arg(b). arg(c).}
A92: p40_versionF | B92: p40 | C92: F | D92: att(b,a). att(b,c). att(c,b). | E92: arg(a). arg(b). arg(c). | F92: in(b) in(c) | G92: ="{"&F92&"}, {}, {"&D92&E92&"}" -> {in(b) in(c)}, {}, {att(b,a). att(b,c). att(c,b). arg(a). arg(b). arg(c).}
A93: p41_versionF | B93: p41 | C93: F | D93: att(a,b). att(b,c). att(c,b). | E93: arg(a). arg(b). arg(c). | F93: in(a) out(b) | G93: ="{"&F93&"}, {}, {"&D93&E93&"}" -> {in(a) out(b)}, {}, {att(a,b). att(b,c). att(c,b). arg(a). arg(b). arg(c).}
A94: p42_versionF | B94: p42 | C94: F | D94: att(a,b). att(b,a). att(c,b). | E94: arg(a). arg(b). arg(c). | F94: out(a) out(b) in(c) | G94: ="{"&F94&"}, {}, {"&D94&E94&"}" -> {out(a) out(b) in(c)}, {}, {att(a,b). att(b,a). att(c,b). arg(a). arg(b). arg(c).}
A95: p43_versionF | B95: p43 | C95: F | D95: att(b,a). att(b,c). att(c,a). att(c,b). | E95: arg(a). arg(b). arg(c). | F95: out(a) out(b) in(c) | G95: ="{"&F95&"}, {}, {"&D95&E95&"}" -> {out(a) out(b) in(c)}, {}, {att(b,a). att(b,c). att(c,a). att(c,b). arg(a). arg(b). arg(c).}
A96: p44_versionF | B96: p44 | C96: F | D96: att(b,a). att(b,c). att(c,b). | E96: arg(a). arg(b). arg(c). | F96: in(a) out(b) in(c) | G96: ="{"&F96&"}, {}, {"&D96&E96&"}" -> {in(a) out(b) in(c)}, {}, {att(b,a). att(b,c). att(c,b). arg(a). arg(b). arg(c).}
A97: p45_versionF | B97: p45 | C97: F | D97: att(a,c). att(b,a). att(c,a). att(c,b). | E97: arg(a). arg(b). arg(c). | F97: in(a) out(b) in(c) | G97: ="{"&F97&"}, {}, {"&D97&E97&"}" -> {in(a) out(b) in(c)}, {}, {att(a,c). att(b,a). att(c,a). att(c,b). arg(a). arg(b). arg(c).}
A98: p46_versionF | B98: p46 | C98: F | D98: att(b,a). att(c,b). | E98: arg(a). arg(b). arg(c). | F98: in(a) out(b) in(c) | G98: ="{"&F98&"}, {}, {"&D98&E98&"}" -> {in(a) out(b) in(c)}, {}, {att(b,a). att(c,b). arg(a). arg(b). arg(c).}
A99: p47_versionF | B99: p47 | C99: F | D99: att(b,a). att(b,c). | E99: arg(a). arg(b). arg(c). | F99: out(a) in(c) | G99: ="{"&F99&"}, {}, {"&D99&E99&"}" -> {out(a) in(c)}, {}, {att(b,a). att(b,c). arg(a). arg(b). arg(c).}
...

Sheet Sheet2
A2: ='Sheet 1'!A2 -> p75_versionA | B2: {in(a) out(b)}, {}, {att(a,b). att(b,a). att(b,c). att(b,d). att(c,b). att(c,d). att(d,b). att(d,c). arg(a). arg(b). arg(c). arg(d).}
A3: ='Sheet 1'!A3 -> p76_versionA | B3: {in(a) out(b)}, {}, {att(a,b). att(b,a). att(b,c). att(c,d). att(d,b). att(d,c). arg(a). arg(b). arg(c). arg(d).}
A4: ='Sheet 1'!A4 -> p77_versionA | B4: {out(a) out(b)}, {}, {att(b,a). att(b,c). att(c,b). att(c,d). att(d,a). att(d,c). arg(a). arg(b). arg(c). arg(d).}
A5: ='Sheet 1'!A5 -> p78_versionA | B5: {in(a) out(b)}, {}, {att(a,b). att(b,a). att(c,b). att(d,b). att(d,c). arg(a). arg(b). arg(c). arg(d).}
A6: ='Sheet 1'!A6 -> p79_versionA | B6: {in(a)}, {}, {att(b,a). att(b,c). att(b,d). att(c,b). att(d,b). arg(a). arg(b). arg(c). arg(d).}
A7: ='Sheet 1'!A7 -> p80_versionA | B7: {out(b) in(d)}, {}, {att(b,a). att(c,b). att(c,d). att(d,c). arg(a). arg(b). arg(c). arg(d).}
A8: ='Sheet 1'!A8 -> p81_versionA | B8: {in(a) out(b)}, {}, {att(a,b). att(b,a). att(c,b). att(d,b). arg(a). arg(b). arg(c). arg(d).}
A9: ='Sheet 1'!A9 -> p82_versionA | B9: {in(a) out(b)}, {}, {att(a,b). att(b,a). att(c,b). att(c,d). att(d,b). att(d,c). arg(a). arg(b). arg(c). arg(d).}
B10: {in(a) out(b)}, {}, {att(a,b). att(b,a). att(c,b). att(d,b). arg(a). arg(b). arg(c). arg(d).}
A11: ='Sheet 1'!A11 -> p84_versionA | B11: {in(a) out(b)}, {}, {att(b,a). att(c,a). att(c,b). att(d,a). att(d,b). arg(a). arg(b). arg(c). arg(d).}
A12: ='Sheet 1'!A12 -> p85_versionA | B12: {in(b) in(c)}, {}, {att(a,b). att(b,a). arg(a). arg(b). arg(c).}
A13: ='Sheet 1'!A13 -> p86_versionA | B13: {in(a) out(b)}, {}, {att(a,b). att(b,a). att(b,c). att(b,d). att(c,b). att(c,d). att(d,b). att(d,c). arg(a). arg(b). arg(c). arg(d).}
A14: ='Sheet 1'!A14 -> p87_versionA | B14: {in(a) in(c) out(e)}, {}, {att(a,b). att(b,a). att(c,b). att(c,e). att(d,b). att(e,b). att(e,d). arg(a). arg(b). arg(c). arg(d). arg(e).}
A15: ='Sheet 1'!A15 -> p88_versionA | B15: {out(a) in(b) in(e)}, {}, {att(b,a). att(c,d). att(d,e). att(e,b). arg(a). arg(b). arg(c). arg(d). arg(e).}
A16: ='Sheet 1'!A16 -> p89_versionA | B16: {in(a) out(b) out(c)}, {}, {att(a,b). att(b,a). att(c,b). att(d,e). att(e,b). arg(a). arg(b). arg(c). arg(d). arg(e).}
A17: ='Sheet 1'!A17 -> p90_versionA | B17: {out(a) out(b) out(c) out(d) out(e)}, {}, {att(a,b). att(b,a). att(c,d). att(d,b). att(d,e). att(e,b). att(e,c). arg(a). arg(b). arg(c). arg(d). arg(e).}
A18: ='Sheet 1'!A18 -> p91_versionA | B18: {in(a) out(b)}, {}, {att(a,b). att(b,a). att(c,d). att(d,e). att(e,c). arg(a). arg(b). arg(c). arg(d). arg(e).}
A19: ='Sheet 1'!A19 -> p92_versionA | B19: {out(a) in(b) out(c) out(d) out(e)}, {}, {att(a,b). att(b,a). att(c,b). att(d,b). att(e,b). arg(a). arg(b). arg(c). arg(d). arg(e).}
A20: ='Sheet 1'!A20 -> p93_versionA | B20: {in(a) out(b)}, {}, {att(b,a). att(c,d). att(d,e). att(e,c). arg(a). arg(b). arg(c). arg(d). arg(e).}
A21: ='Sheet 1'!A21 -> p94_versionA | B21: {out(a) in(c) in(e)}, {}, {att(a,b). att(b,a). att(b,e). att(c,d). att(d,c). att(e,a). att(e,b). arg(a). arg(b). arg(c). arg(d). arg(e).}
A22: ='Sheet 1'!A22 -> p100_versionB | B22: {in(c) in(d) in(e)}, {}, {att(a,b). att(b,a). att(c,b). att(c,d). att(d,b). att(d,e). att(e,b). att(e,c). arg(a). arg(b). arg(c). arg(d). arg(e).}
... A37: ='Sheet 1'!A37 -> p95_versionB | B37: {in(a) out(b) in(c)}, {}, {att(a,b). att(b,a). att(c,b). arg(a). arg(b). arg(c).}
B38: {in(a) out(b) in(c)}, {}, {att(a,b). att(b,a). att(c,b). arg(a). arg(b). arg(c).}
B39: {in(a) out(b) in(c)}, {}, {att(b,a). att(c,b). arg(a). arg(b). arg(c).}
A40: ='Sheet 1'!A40 -> p98_versionB | B40: {in(a) in(b) in(c)}, {}, {att(a,b). att(b,a). att(c,b). arg(a). arg(b). arg(c).}
B41: {in(a) out(b)}, {}, {att(a,b). att(b,a). att(c,b). att(c,d). att(d,b). att(d,c). arg(a). arg(b). arg(c). arg(d).}
A42: ='Sheet 1'!A42 -> p55_versionC | B42: {in(a) out(b)}, {}, {att(b,a). att(b,c). att(b,d). att(c,b). att(d,b). att(d,c). arg(a). arg(b). arg(c). arg(d).}
A43: ='Sheet 1'!A43 -> p56_versionC | B43: {in(a) out(b)}, {}, {att(a,b). att(b,a). att(c,b). att(c,e). att(d,b). att(e,b). att(e,c). arg(a). arg(b). arg(c). arg(d). arg(e).}
A44: ='Sheet 1'!A44 -> p57_versionC | B44: {in(a) out(b) out(c) in(d)}, {}, {att(b,a). att(c,b). att(d,b). att(d,c). arg(a). arg(b). arg(c). arg(d).}
A45: ='Sheet 1'!A45 -> p58_versionC | B45: {in(a) out(b)}, {}, {att(b,a). att(b,c). att(b,d). att(c,b). att(c,d). att(d,b). att(d,c). arg(a). arg(b). arg(c). arg(d).}
B46: {in(a) out(b) in(c)}, {}, {att(b,a). att(c,b). arg(a). arg(b). arg(c).}
A47: ='Sheet 1'!A47 -> p60_versionC | B47: {out(a) in(c)}, {}, {att(a,b). att(b,a). att(c,a). att(c,b). arg(a). arg(b). arg(c).}
B48: {in(a) out(b) in(c)}, {}, {att(b,a). att(c,b). arg(a). arg(b). arg(c).}
A49: ='Sheet 1'!A49 -> p62_versionC | B49: {in(a)}, {}, {att(b,a). att(c,b). arg(a). arg(b). arg(c).}
A50: ='Sheet 1'!A50 -> p63_versionC | B50: {in(b)}, {}, {att(b,a). att(b,c). att(c,b). arg(a). arg(b). arg(c).}
A51: ='Sheet 1'!A51 -> p64_versionC | B51: {in(c)}, {}, {att(b,a). att(c,b). arg(a). arg(b). arg(c).}
B52: {in(a) out(b) in(c)}, {}, {att(b,a). att(c,b). arg(a). arg(b). arg(c).}
B53: {in(a) out(b) in(c)}, {}, {att(a,b). att(b,a). att(c,b). arg(a). arg(b). arg(c).}
A54: ='Sheet 1'!A54 -> p67_versionC | B54: {in(a) out(b)}, {}, {att(b,a). att(c,b). att(c,d). att(d,a). att(d,b). att(d,c). att(e,b). arg(a). arg(b). arg(c). arg(d). arg(e).}
A55: ='Sheet 1'!A55 -> p68_versionC | B55: {}, {}, {att(b,a). att(c,b). arg(a). arg(b). arg(c).}
...

Sheet Sheet3
A2: p75_versionA | B2: =RIGHT(A2,1) -> A | C2: {in(a), out(b)}, {}, {att(a,b). att(b,a). att(b,c). att(b,d). att(c,b). att(c,d). att(d,b). att(d,c). arg(a). arg(b). arg(c). arg(d).}
A3: p76_versionA | B3: =RIGHT(A3,1) -> A | C3: {in(a), out(b)}, {}, {att(a,b). att(b,a). att(b,c). att(c,d). att(d,b). att(d,c). arg(a). arg(b). arg(c). arg(d).}
A4: p77_versionA | B4: =RIGHT(A4,1) -> A | C4: {out(a), out(b)}, {}, {att(b,a). att(b,c). att(c,b). att(c,d). att(d,a). att(d,c). arg(a). arg(b). arg(c). arg(d).}
A5: p78_versionA | B5: =RIGHT(A5,1) -> A | C5: {in(a), out(b)}, {}, {att(a,b). att(b,a). att(c,b). att(d,b). att(d,c). arg(a). arg(b). arg(c). arg(d).}
A6: p79_versionA | B6: =RIGHT(A6,1) -> A | C6: {in(a)}, {}, {att(b,a). att(b,c). att(b,d). att(c,b). att(d,b). arg(a). arg(b). arg(c). arg(d).}
A7: p80_versionA | B7: =RIGHT(A7,1) -> A | C7: {out(b), in(d)}, {}, {att(b,a). att(c,b). att(c,d). att(d,c). arg(a). arg(b). arg(c). arg(d).}
A8: p81_versionA | B8: =RIGHT(A8,1) -> A | C8: {in(a), out(b)}, {}, {att(a,b). att(b,a). att(c,b). att(d,b). arg(a). arg(b). arg(c). arg(d).}
A9: p82_versionA | B9: =RIGHT(A9,1) -> A | C9: {in(a), out(b)}, {}, {att(a,b). att(b,a). att(c,b). att(c,d). att(d,b). att(d,c). arg(a). arg(b). arg(c). arg(d).}
A10: p84_versionA | B10: =RIGHT(A10,1) -> A | C10: {in(a), out(b)}, {}, {att(b,a). att(c,a). att(c,b). att(d,a). att(d,b). arg(a). arg(b). arg(c). arg(d).}
A11: p85_versionA | B11: =RIGHT(A11,1) -> A | C11: {in(b), in(c)}, {}, {att(a,b). att(b,a). arg(a). arg(b). arg(c).}
A12: p86_versionA | B12: =RIGHT(A12,1) -> A | C12: {in(a), out(b)}, {}, {att(a,b). att(b,a). att(b,c). att(b,d). att(c,b). att(c,d). att(d,b). att(d,c). arg(a). arg(b). arg(c). arg(d).}
A13: p87_versionA | B13: =RIGHT(A13,1) -> A | C13: {in(a), in(c), out(e)}, {}, {att(a,b). att(b,a). att(c,b). att(c,e). att(d,b). att(e,b). att(e,d). arg(a). arg(b). arg(c). arg(d). arg(e).}
... A107: p5_versionG | B107: =RIGHT(A107,1) -> G | C107: {out(b), in(c)}, {}, {att(a,b). att(b,a). arg(a). arg(b). arg(c).}
