Workbook

Sheet PART_A
A1: PARTICIPANT | B1: GROUP_TOTAL | C1: VERSION | D1: GROUP_IDENTITY | E1: PARTICIPANT_IDENTITY | F1: RELATION | G1: EXPECTED | H1: GROUP_RESPONSE | I1: GROUP_CORRECT_RESPONSE | J1: 1st_RESPONSE | K1: 1st_CORRECT_RESPONSE | L1: 1st_CONFIDENCE | M1: INFLUENCE_GROUP | N1: AGREEMENT | O1: 2nd_RESPONSE | P1: 2nd_CORRECT_RESPONSE | Q1: FOLLOW_GROUP | R1: MIND_CHANGE | S1: ATTACK_CHANGE | T1: 2nd_CONFIDENCE
A2: 1 | B2: 1 | C2: G | D2: 1 | E2: 1 | F2: A_attacks_B | G2: No_attack | H2: No_attack | I2: 1 | J2: Attack | K2: 0 | L2: 2 | M2: 0 | N2: 3 | O2: No_attack | P2: 1 | Q2: 1 | R2: 3 | S2: 1 | T2: 2
A3: 1 | B3: 1 | C3: G | D3: 1 | E3: 1 | F3: A_attacks_C | G3: No_attack | H3: No_attack | I3: 1 | J3: No_attack | K3: 1 | L3: 2 | M3: 1 | N3: 3 | O3: No_attack | P3: 1 | Q3: 1 | R3: 3 | S3: 0 | T3: 2
A4: 1 | B4: 1 | C4: G | D4: 1 | E4: 1 | F4: A_attacks_D | G4: No_attack | H4: No_attack | I4: 1 | J4: No_attack | K4: 1 | L4: 2 | M4: 1 | N4: 3 | O4: No_attack | P4: 1 | Q4: 1 | R4: 3 | S4: 0 | T4: 2
A5: 1 | B5: 1 | C5: G | D5: 1 | E5: 1 | F5: A_attacks_E | G5: No_attack | H5: No_attack | I5: 1 | J5: No_attack | K5: 1 | L5: 2 | M5: 1 | N5: 3 | O5: No_attack | P5: 1 | Q5: 1 | R5: 3 | S5: 0 | T5: 2
A6: 1 | B6: 1 | C6: G | D6: 1 | E6: 1 | F6: B_attacks_A | G6: Attack | H6: Attack | I6: 1 | J6: Attack | K6: 1 | L6: 2 | M6: 1 | N6: 3 | O6: Attack | P6: 1 | Q6: 1 | R6: 3 | S6: 0 | T6: 2
A7: 1 | B7: 1 | C7: G | D7: 1 | E7: 1 | F7: B_attacks_C | G7: No_attack | H7: No_attack | I7: 1 | J7: No_attack | K7: 1 | L7: 2 | M7: 1 | N7: 3 | O7: No_attack | P7: 1 | Q7: 1 | R7: 3 | S7: 0 | T7: 2
A8: 1 | B8: 1 | C8: G | D8: 1 | E8: 1 | F8: B_attacks_D | G8: No_attack | H8: No_attack | I8: 1 | J8: No_attack | K8: 1 | L8: 2 | M8: 1 | N8: 3 | O8: No_attack | P8: 1 | Q8: 1 | R8: 3 | S8: 0 | T8: 2
A9: 1 | B9: 1 | C9: G | D9: 1 | E9: 1 | F9: B_attacks_E | G9: No_attack | H9: No_attack | I9: 1 | J9: No_attack | K9: 1 | L9: 2 | M9: 1 | N9: 3 | O9: No_attack | P9: 1 | Q9: 1 | R9: 3 | S9: 0 | T9: 2
A10: 1 | B10: 1 | C10: G | D10: 1 | E10: 1 | F10: C_attacks_A | G10: No_attack | H10: No_attack | I10: 1 | J10: No_attack | K10: 1 | L10: 2 | M10: 1 | N10: 3 | O10: No_attack | P10: 1 | Q10: 1 | R10: 3 | S10: 0 | T10: 2
A11: 1 | B11: 1 | C11: G | D11: 1 | E11: 1 | F11: C_attacks_B | G11: Attack | H11: Attack | I11: 1 | J11: Attack | K11: 1 | L11: 2 | M11: 1 | N11: 3 | O11: Attack | P11: 1 | Q11: 1 | R11: 3 | S11: 0 | T11: 2
A12: 1 | B12: 1 | C12: G | D12: 1 | E12: 1 | F12: C_attacks_D | G12: Attack | H12: Attack | I12: 1 | J12: No_attack | K12: 0 | L12: 2 | M12: 0 | N12: 3 | O12: Attack | P12: 1 | Q12: 1 | R12: 3 | S12: 1 | T12: 2
A13: 1 | B13: 1 | C13: G | D13: 1 | E13: 1 | F13: C_attacks_E | G13: No_attack | H13: No_attack | I13: 1 | J13: Attack | K13: 0 | L13: 2 | M13: 0 | N13: 3 | O13: No_attack | P13: 1 | Q13: 1 | R13: 3 | S13: 1 | T13: 2
... A21: 1 | B21: 1 | C21: G | D21: 1 | E21: 1 | F21: E_attacks_D | G21: No_attack | H21: No_attack | I21: 1 | J21: No_attack | K21: 1 | L21: 2 | M21: 1 | N21: 3 | O21: No_attack | P21: 1 | Q21: 1 | R21: 3 | S21: 0 | T21: 2
A22: 2 | B22: 1 | C22: G | D22: 1 | E22: 2 | F22: A_attacks_B | G22: No_attack | H22: No_attack | I22: 1 | J22: No_attack | K22: 1 | L22: 1 | M22: 1 | N22: 2 | O22: NA | P22: NA | Q22: NA | R22: 3 | S22: NA | T22: 3
A23: 2 | B23: 1 | C23: G | D23: 1 | E23: 2 | F23: A_attacks_C | G23: No_attack | H23: No_attack | I23: 1 | J23: No_attack | K23: 1 | L23: 1 | M23: 1 | N23: 2 | O23: NA | P23: NA | Q23: NA | R23: 3 | S23: NA | T23: 3
A24: 2 | B24: 1 | C24: G | D24: 1 | E24: 2 | F24: A_attacks_D | G24: No_attack | H24: No_attack | I24: 1 | J24: No_attack | K24: 1 | L24: 1 | M24: 1 | N24: 2 | O24: NA | P24: NA | Q24: NA | R24: 3 | S24: NA | T24: 3
A25: 2 | B25: 1 | C25: G | D25: 1 | E25: 2 | F25: A_attacks_E | G25: No_attack | H25: No_attack | I25: 1 | J25: No_attack | K25: 1 | L25: 1 | M25: 1 | N25: 2 | O25: NA | P25: NA | Q25: NA | R25: 3 | S25: NA | T25: 3
A26: 2 | B26: 1 | C26: G | D26: 1 | E26: 2 | F26: B_attacks_A | G26: Attack | H26: Attack | I26: 1 | J26: Attack | K26: 1 | L26: 1 | M26: 1 | N26: 2 | O26: NA | P26: NA | Q26: NA | R26: 3 | S26: NA | T26: 3
A27: 2 | B27: 1 | C27: G | D27: 1 | E27: 2 | F27: B_attacks_C | G27: No_attack | H27: No_attack | I27: 1 | J27: No_attack | K27: 1 | L27: 1 | M27: 1 | N27: 2 | O27: NA | P27: NA | Q27: NA | R27: 3 | S27: NA | T27: 3
A28: 2 | B28: 1 | C28: G | D28: 1 | E28: 2 | F28: B_attacks_D | G28: No_attack | H28: No_attack | I28: 1 | J28: No_attack | K28: 1 | L28: 1 | M28: 1 | N28: 2 | O28: NA | P28: NA | Q28: NA | R28: 3 | S28: NA | T28: 3
A29: 2 | B29: 1 | C29: G | D29: 1 | E29: 2 | F29: B_attacks_E | G29: No_attack | H29: No_attack | I29: 1 | J29: No_attack | K29: 1 | L29: 1 | M29: 1 | N29: 2 | O29: NA | P29: NA | Q29: NA | R29: 3 | S29: NA | T29: 3
A30: 2 | B30: 1 | C30: G | D30: 1 | E30: 2 | F30: C_attacks_A | G30: No_attack | H30: No_attack | I30: 1 | J30: No_attack | K30: 1 | L30: 1 | M30: 1 | N30: 2 | O30: NA | P30: NA | Q30: NA | R30: 3 | S30: NA | T30: 3
A31: 2 | B31: 1 | C31: G | D31: 1 | E31: 2 | F31: C_attacks_B | G31: Attack | H31: Attack | I31: 1 | J31: Attack | K31: 1 | L31: 1 | M31: 1 | N31: 2 | O31: NA | P31: NA | Q31: NA | R31: 3 | S31: NA | T31: 3
A32: 2 | B32: 1 | C32: G | D32: 1 | E32: 2 | F32: C_attacks_D | G32: Attack | H32: Attack | I32: 1 | J32: Attack | K32: 1 | L32: 1 | M32: 1 | N32: 2 | O32: NA | P32: NA | Q32: NA | R32: 3 | S32: NA | T32: 3
A33: 2 | B33: 1 | C33: G | D33: 1 | E33: 2 | F33: C_attacks_E | G33: No_attack | H33: No_attack | I33: 1 | J33: No_attack | K33: 1 | L33: 1 | M33: 1 | N33: 2 | O33: NA | P33: NA | Q33: NA | R33: 3 | S33: NA | T33: 3
... A41: 2 | B41: 1 | C41: G | D41: 1 | E41: 2 | F41: E_attacks_D | G41: No_attack | H41: No_attack | I41: 1 | J41: No_attack | K41: 1 | L41: 1 | M41: 1 | N41: 2 | O41: NA | P41: NA | Q41: NA | R41: 3 | S41: NA | T41: 3
A42: 3 | B42: 1 | C42: G | D42: 1 | E42: 3 | F42: A_attacks_B | G42: No_attack | H42: No_attack | I42: 1 | J42: Attack | K42: 0 | L42: 2 | M42: 0 | N42: 3 | O42: Attack | P42: 0 | Q42: 0 | R42: 2 | S42: 0 | T42: 3
A43: 3 | B43: 1 | C43: G | D43: 1 | E43: 3 | F43: A_attacks_C | G43: No_attack | H43: No_attack | I43: 1 | J43: No_attack | K43: 1 | L43: 2 | M43: 1 | N43: 3 | O43: No_attack | P43: 1 | Q43: 1 | R43: 2 | S43: 0 | T43: 3
A44: 3 | B44: 1 | C44: G | D44: 1 | E44: 3 | F44: A_attacks_D | G44: No_attack | H44: No_attack | I44: 1 | J44: No_attack | K44: 1 | L44: 2 | M44: 1 | N44: 3 | O44: No_attack | P44: 1 | Q44: 1 | R44: 2 | S44: 0 | T44: 3
A45: 3 | B45: 1 | C45: G | D45: 1 | E45: 3 | F45: A_attacks_E | G45: No_attack | H45: No_attack | I45: 1 | J45: No_attack | K45: 1 | L45: 2 | M45: 1 | N45: 3 | O45: No_attack | P45: 1 | Q45: 1 | R45: 2 | S45: 0 | T45: 3
A46: 3 | B46: 1 | C46: G | D46: 1 | E46: 3 | F46: B_attacks_A | G46: Attack | H46: Attack | I46: 1 | J46: Attack | K46: 1 | L46: 2 | M46: 1 | N46: 3 | O46: Attack | P46: 1 | Q46: 1 | R46: 2 | S46: 0 | T46: 3
A47: 3 | B47: 1 | C47: G | D47: 1 | E47: 3 | F47: B_attacks_C | G47: No_attack | H47: No_attack | I47: 1 | J47: No_attack | K47: 1 | L47: 2 | M47: 1 | N47: 3 | O47: No_attack | P47: 1 | Q47: 1 | R47: 2 | S47: 0 | T47: 3
A48: 3 | B48: 1 | C48: G | D48: 1 | E48: 3 | F48: B_attacks_D | G48: No_attack | H48: No_attack | I48: 1 | J48: No_attack | K48: 1 | L48: 2 | M48: 1 | N48: 3 | O48: No_attack | P48: 1 | Q48: 1 | R48: 2 | S48: 0 | T48: 3
A49: 3 | B49: 1 | C49: G | D49: 1 | E49: 3 | F49: B_attacks_E | G49: No_attack | H49: No_attack | I49: 1 | J49: No_attack | K49: 1 | L49: 2 | M49: 1 | N49: 3 | O49: No_attack | P49: 1 | Q49: 1 | R49: 2 | S49: 0 | T49: 3
A50: 3 | B50: 1 | C50: G | D50: 1 | E50: 3 | F50: C_attacks_A | G50: No_attack | H50: No_attack | I50: 1 | J50: No_attack | K50: 1 | L50: 2 | M50: 1 | N50: 3 | O50: No_attack | P50: 1 | Q50: 1 | R50: 2 | S50: 0 | T50: 3
A51: 3 | B51: 1 | C51: G | D51: 1 | E51: 3 | F51: C_attacks_B | G51: Attack | H51: Attack | I51: 1 | J51: Attack | K51: 1 | L51: 2 | M51: 1 | N51: 3 | O51: Attack | P51: 1 | Q51: 1 | R51: 2 | S51: 0 | T51: 3
A52: 3 | B52: 1 | C52: G | D52: 1 | E52: 3 | F52: C_attacks_D | G52: Attack | H52: Attack | I52: 1 | J52: No_attack | K52: 0 | L52: 2 | M52: 0 | N52: 3 | O52: No_attack | P52: 0 | Q52: 0 | R52: 2 | S52: 0 | T52: 3
A53: 3 | B53: 1 | C53: G | D53: 1 | E53: 3 | F53: C_attacks_E | G53: No_attack | H53: No_attack | I53: 1 | J53: No_attack | K53: 1 | L53: 2 | M53: 1 | N53: 3 | O53: No_attack | P53: 1 | Q53: 1 | R53: 2 | S53: 0 | T53: 3
... A245: 25 | B245: 8 | C245: E | D245: 3 | E245: 1 | F245: C_attacks_B | G245: Attack | H245: Attack | I245: 1 | J245: Attack | K245: 1 | L245: 4 | M245: 1 | N245: 3 | O245: Attack | P245: 1 | Q245: 1 | R245: 2 | S245: 0 | T245: 3
...

Sheet PART_B
A1: PARTICIPANT | B1: GROUP_TOTAL | C1: VERSION | D1: GROUP_IDENTITY | E1: PARTICIPANT_IDENTITY | F1: ITEM | G1: EXP_GROUNDED | H1: EXP_PREFERRED | I1: EXP_CF2 | J1: GROUP_RESP | K1: GROUP_CORRECT_GROUNDED | L1: GROUP_CORRECT_PREFERRED | M1: GROUP_CORRECT_CF2 | N1: 1st_RESPONSE | O1: 1st_CORRECT_GROUNDED | P1: 1st_CORRECT_PREFERRED | Q1: 1st_CORRECT_CF2 | R1: 1st_CONFIDENCE | S1: INFLUENCE_GROUP | T1: AGREEMENT | U1: 2nd_RESPONSE | V1: 2nd_CORRECT_GROUNDED | W1: 2nd_CORRECT_PREFERRED | X1: 2nd_CORRECT_CF2 | Y1: FOLLOW_GROUP | Z1: MIND_CHANGE | AA1: ACCEPT_CHANGE | AB1: 2nd_CONFIDENCE | AC1: GROUP_PRED_GROUNDED | AD1: GROUP_PRED_PREFERRED | AE1: GROUP_PRED_CF2 | AF1: 2nd_PRED_GROUNDED | AG1: 2nd_PRED_PREFERRED | AH1: 2nd_PRED_CF2 | AI1: GPG_G-CORRECT | AJ1: GPP_G-CORRECT | AK1: GPC_G-CORRECT | AL1: GPG_1-CORRECT | AM1: GPP_1-CORRECT | AN1: GPC_1-CORRECT | AO1: 2PG_1-CORRECT | AP1: 2PP_1-CORRECT | AQ1: 2PC_1-CORRECT | AR1: GPG_2-CORRECT | AS1: GPP_2-CORRECT | AT1: GPC_2-CORRECT | AU1: 2PG_2-CORRECT | AV1: 2PP_2-CORRECT | AW1: 2PC_2-CORRECT | AX1: MAJ_GRAPH_PRED_GROUNDED | AY1: MAJ_GRAPH_PRED_PREFERRED | AZ1: MAJ_GRAPH_PRED_CF2 | BA1: MPG_G-CORRECT | BB1: MPP_G-CORRECT | BC1: MPC_G-CORRECT | BD1: MPG_1-CORRECT | BE1: MPP_1-CORRECT | BF1: MPC_1-CORRECT | BG1: MPG_2-CORRECT | BH1: MPP_2-CORRECT | BI1: MPC_2-CORRECT | BJ1: PREF-CF2_DIFF | BK1: GROUN-PREF_DIFF | BL1: GROUN-CF2_DIFF | BM1: GGROUN-CF2_DIFF | BN1: GPREF-CF2_DIFF | BO1: GCF2-CF2_DIFF | BP1: 2GROUND-CF2_DIFF | BQ1: 2PREF-CF2_DIFF | BR1: 2CF2-CF2_DIFF | BS1: MGROUND-CF2_DIFF | BT1: MPREF-CF2_DIFF | BU1: MCF2-CF2_DIFF | BV1: GROUP_ID_AND_ITEM | BW1: 1ST_PART_GROUP | BX1: 1ST_PART_GROUP_CORRECT_GROUNDED | BY1: 1ST_PART_GROUP_CORRECT_PREFERRED | BZ1: 1ST_PART_GROUP_CORRECT_CF2 | CA1: 1ST_PART_GPG_G-CORRECT | CB1: 1ST_PART_GPP_G-CORRECT | CC1: 1ST_PART_GPC_G-CORRECT | CD1: 1ST_MPG_G-CORRECT | CE1: 1ST_MPP_G-CORRECT | CF1: 1ST_MPC_G-CORRECT
A2: 1 | B2: 1 | C2: G | D2: 1 | E2: 1 | F2: A | G2: Undecided | H2: Undecided | I2: Accept | J2: Accept | K2: 0 | L2: 0 | M2: 1 | N2: Accept | O2: 0 | P2: 0 | Q2: 1 | R2: 2 | S2: 1 | T2: 3 | U2: Accept | V2: 0 | W2: 0 | X2: 1 | Y2: 1 | Z2: 3 | AA2: 0 | AB2: 2 | AC2: Undecided | AD2: Undecided | AE2: Accept | AF2: Undecided | AG2: Undecided | AH2: Accept | AI2: 0 | AJ2: 0 | AK2: 1 | AL2: 0 | AM2: 0 | AN2: 1 | AO2: 0 | AP2: 0 | AQ2: 1 | AR2: 0 | AS2: 0 | AT2: 1 | AU2: 0 | AV2: 0 | AW2: 1 | AX2: Undecided | AY2: Accept | AZ2: Accept | BA2: 0 | BB2: 1 | BC2: 1 | BD2: 0 | BE2: 1 | BF2: 1 | BG2: 0 | BH2: 1 | BI2: 1 | BJ2: 1 | BK2: 0 | BL2: 1 | BM2: 1 | BN2: 1 | BO2: 0 | BP2: 1 | BQ2: 1 | BR2: 0 | BS2: 1 | BT2: 0 | BU2: 0 | BV2: 1A | BW2: 1 | BX2: 0 | BY2: 0 | BZ2: 1 | CA2: 0 | CB2: 0 | CC2: 1 | CD2: 0 | CE2: 1 | CF2: 1
A3: 1 | B3: 1 | C3: G | D3: 1 | E3: 1 | F3: B | G3: Undecided | H3: Undecided | I3: Reject | J3: Reject | K3: 0 | L3: 0 | M3: 1 | N3: Reject | O3: 0 | P3: 0 | Q3: 1 | R3: 2 | S3: 1 | T3: 3 | U3: Reject | V3: 0 | W3: 0 | X3: 1 | Y3: 1 | Z3: 3 | AA3: 0 | AB3: 2 | AC3: Undecided | AD3: Undecided | AE3: Reject | AF3: Undecided | AG3: Undecided | AH3: Reject | AI3: 0 | AJ3: 0 | AK3: 1 | AL3: 0 | AM3: 0 | AN3: 1 | AO3: 0 | AP3: 0 | AQ3: 1 | AR3: 0 | AS3: 0 | AT3: 1 | AU3: 0 | AV3: 0 | AW3: 1 | AX3: Undecided | AY3: Reject | AZ3: Reject | BA3: 0 | BB3: 1 | BC3: 1 | BD3: 0 | BE3: 1 | BF3: 1 | BG3: 0 | BH3: 1 | BI3: 1 | BJ3: 1 | BK3: 0 | BL3: 1 | BM3: 1 | BN3: 1 | BO3: 0 | BP3: 1 | BQ3: 1 | BR3: 0 | BS3: 1 | BT3: 0 | BU3: 0 | BV3: 1B | BW3: 1 | BX3: 0 | BY3: 0 | BZ3: 1 | CA3: 0 | CB3: 0 | CC3: 1 | CD3: 0 | CE3: 1 | CF3: 1
A4: 1 | B4: 1 | C4: G | D4: 1 | E4: 1 | F4: C | G4: Undecided | H4: Undecided | I4: Undecided | J4: Undecided | K4: 1 | L4: 1 | M4: 1 | N4: Undecided | O4: 1 | P4: 1 | Q4: 1 | R4: 2 | S4: 1 | T4: 3 | U4: Undecided | V4: 1 | W4: 1 | X4: 1 | Y4: 1 | Z4: 3 | AA4: 0 | AB4: 2 | AC4: Undecided | AD4: Undecided | AE4: Undecided | AF4: Undecided | AG4: Undecided | AH4: Undecided | AI4: 1 | AJ4: 1 | AK4: 1 | AL4: 1 | AM4: 1 | AN4: 1 | AO4: 1 | AP4: 1 | AQ4: 1 | AR4: 1 | AS4: 1 | AT4: 1 | AU4: 1 | AV4: 1 | AW4: 1 | AX4: Undecided | AY4: Undecided | AZ4: Undecided | BA4: 1 | BB4: 1 | BC4: 1 | BD4: 1 | BE4: 1 | BF4: 1 | BG4: 1 | BH4: 1 | BI4: 1 | BJ4: 0 | BK4: 0 | BL4: 0 | BM4: 0 | BN4: 0 | BO4: 0 | BP4: 0 | BQ4: 0 | BR4: 0 | BS4: 0 | BT4: 0 | BU4: 0 | BV4: 1C | BW4: 1 | BX4: 1 | BY4: 1 | BZ4: 1 | CA4: 1 | CB4: 1 | CC4: 1 | CD4: 1 | CE4: 1 | CF4: 1
A5: 1 | B5: 1 | C5: G | D5: 1 | E5: 1 | F5: D | G5: Undecided | H5: Undecided | I5: Undecided | J5: Undecided | K5: 1 | L5: 1 | M5: 1 | N5: Undecided | O5: 1 | P5: 1 | Q5: 1 | R5: 2 | S5: 1 | T5: 3 | U5: Undecided | V5: 1 | W5: 1 | X5: 1 | Y5: 1 | Z5: 3 | AA5: 0 | AB5: 2 | AC5: Undecided | AD5: Undecided | AE5: Undecided | AF5: Undecided | AG5: Undecided | AH5: Undecided | AI5: 1 | AJ5: 1 | AK5: 1 | AL5: 1 | AM5: 1 | AN5: 1 | AO5: 1 | AP5: 1 | AQ5: 1 | AR5: 1 | AS5: 1 | AT5: 1 | AU5: 1 | AV5: 1 | AW5: 1 | AX5: Undecided | AY5: Undecided | AZ5: Undecided | BA5: 1 | BB5: 1 | BC5: 1 | BD5: 1 | BE5: 1 | BF5: 1 | BG5: 1 | BH5: 1 | BI5: 1 | BJ5: 0 | BK5: 0 | BL5: 0 | BM5: 0 | BN5: 0 | BO5: 0 | BP5: 0 | BQ5: 0 | BR5: 0 | BS5: 0 | BT5: 0 | BU5: 0 | BV5: 1D | BW5: 1 | BX5: 1 | BY5: 1 | BZ5: 1 | CA5: 1 | CB5: 1 | CC5: 1 | CD5: 1 | CE5: 1 | CF5: 1
A6: 1 | B6: 1 | C6: G | D6: 1 | E6: 1 | F6: E | G6: Undecided | H6: Undecided | I6: Undecided | J6: Undecided | K6: 1 | L6: 1 | M6: 1 | N6: Undecided | O6: 1 | P6: 1 | Q6: 1 | R6: 2 | S6: 1 | T6: 3 | U6: Undecided | V6: 1 | W6: 1 | X6: 1 | Y6: 1 | Z6: 3 | AA6: 0 | AB6: 2 | AC6: Undecided | AD6: Undecided | AE6: Undecided | AF6: Undecided | AG6: Undecided | AH6: Undecided | AI6: 1 | AJ6: 1 | AK6: 1 | AL6: 1 | AM6: 1 | AN6: 1 | AO6: 1 | AP6: 1 | AQ6: 1 | AR6: 1 | AS6: 1 | AT6: 1 | AU6: 1 | AV6: 1 | AW6: 1 | AX6: Undecided | AY6: Undecided | AZ6: Undecided | BA6: 1 | BB6: 1 | BC6: 1 | BD6: 1 | BE6: 1 | BF6: 1 | BG6: 1 | BH6: 1 | BI6: 1 | BJ6: 0 | BK6: 0 | BL6: 0 | BM6: 0 | BN6: 0 | BO6: 0 | BP6: 0 | BQ6: 0 | BR6: 0 | BS6: 0 | BT6: 0 | BU6: 0 | BV6: 1E | BW6: 1 | BX6: 1 | BY6: 1 | BZ6: 1 | CA6: 1 | CB6: 1 | CC6: 1 | CD6: 1 | CE6: 1 | CF6: 1
A7: 2 | B7: 1 | C7: G | D7: 1 | E7: 2 | F7: A | G7: Undecided | H7: Undecided | I7: Accept | J7: Accept | K7: 0 | L7: 0 | M7: 1 | N7: Accept | O7: 0 | P7: 0 | Q7: 1 | R7: 1 | S7: 1 | T7: 4 | U7: Accept | V7: 0 | W7: 0 | X7: 1 | Y7: 1 | Z7: 1 | AA7: 0 | AB7: 4 | AC7: Undecided | AD7: Undecided | AE7: Accept | AF7: NA | AG7: NA | AH7: NA | AI7: 0 | AJ7: 0 | AK7: 1 | AL7: 0 | AM7: 0 | AN7: 1 | AO7: NA | AP7: NA | AQ7: NA | AR7: 0 | AS7: 0 | AT7: 1 | AU7: NA | AV7: NA | AW7: NA | AX7: Undecided | AY7: Accept | AZ7: Accept | BA7: 0 | BB7: 1 | BC7: 1 | BD7: 0 | BE7: 1 | BF7: 1 | BG7: 0 | BH7: 1 | BI7: 1 | BJ7: 1 | BK7: 0 | BL7: 1 | BM7: 1 | BN7: 1 | BO7: 0 | BP7: 1 | BQ7: 1 | BR7: 1 | BS7: 1 | BT7: 0 | BU7: 0 | BV7: 1A | BW7: 0 | BX7: 0 | BY7: 0 | BZ7: 0 | CA7: 0 | CB7: 0 | CC7: 0 | CD7: 0 | CE7: 0 | CF7: 0
A8: 2 | B8: 1 | C8: G | D8: 1 | E8: 2 | F8: B | G8: Undecided | H8: Undecided | I8: Reject | J8: Reject | K8: 0 | L8: 0 | M8: 1 | N8: Reject | O8: 0 | P8: 0 | Q8: 1 | R8: 1 | S8: 1 | T8: 4 | U8: Reject | V8: 0 | W8: 0 | X8: 1 | Y8: 1 | Z8: 1 | AA8: 0 | AB8: 4 | AC8: Undecided | AD8: Undecided | AE8: Reject | AF8: NA | AG8: NA | AH8: NA | AI8: 0 | AJ8: 0 | AK8: 1 | AL8: 0 | AM8: 0 | AN8: 1 | AO8: NA | AP8: NA | AQ8: NA | AR8: 0 | AS8: 0 | AT8: 1 | AU8: NA | AV8: NA | AW8: NA | AX8: Undecided | AY8: Reject | AZ8: Reject | BA8: 0 | BB8: 1 | BC8: 1 | BD8: 0 | BE8: 1 | BF8: 1 | BG8: 0 | BH8: 1 | BI8: 1 | BJ8: 1 | BK8: 0 | BL8: 1 | BM8: 1 | BN8: 1 | BO8: 0 | BP8: 1 | BQ8: 1 | BR8: 1 | BS8: 1 | BT8: 0 | BU8: 0 | BV8: 1B | BW8: 0 | BX8: 0 | BY8: 0 | BZ8: 0 | CA8: 0 | CB8: 0 | CC8: 0 | CD8: 0 | CE8: 0 | CF8: 0
A9: 2 | B9: 1 | C9: G | D9: 1 | E9: 2 | F9: C | G9: Undecided | H9: Undecided | I9: Undecided | J9: Undecided | K9: 1 | L9: 1 | M9: 1 | N9: Undecided | O9: 1 | P9: 1 | Q9: 1 | R9: 1 | S9: 1 | T9: 4 | U9: Undecided | V9: 1 | W9: 1 | X9: 1 | Y9: 1 | Z9: 1 | AA9: 0 | AB9: 4 | AC9: Undecided | AD9: Undecided | AE9: Undecided | AF9: NA | AG9: NA | AH9: NA | AI9: 1 | AJ9: 1 | AK9: 1 | AL9: 1 | AM9: 1 | AN9: 1 | AO9: NA | AP9: NA | AQ9: NA | AR9: 1 | AS9: 1 | AT9: 1 | AU9: NA | AV9: NA | AW9: NA | AX9: Undecided | AY9: Undecided | AZ9: Undecided | BA9: 1 | BB9: 1 | BC9: 1 | BD9: 1 | BE9: 1 | BF9: 1 | BG9: 1 | BH9: 1 | BI9: 1 | BJ9: 0 | BK9: 0 | BL9: 0 | BM9: 0 | BN9: 0 | BO9: 0 | BP9: 1 | BQ9: 1 | BR9: 1 | BS9: 0 | BT9: 0 | BU9: 0 | BV9: 1C | BW9: 0 | BX9: 0 | BY9: 0 | BZ9: 0 | CA9: 0 | CB9: 0 | CC9: 0 | CD9: 0 | CE9: 0 | CF9: 0
A10: 2 | B10: 1 | C10: G | D10: 1 | E10: 2 | F10: D | G10: Undecided | H10: Undecided | I10: Undecided | J10: Undecided | K10: 1 | L10: 1 | M10: 1 | N10: Undecided | O10: 1 | P10: 1 | Q10: 1 | R10: 1 | S10: 1 | T10: 4 | U10: Undecided | V10: 1 | W10: 1 | X10: 1 | Y10: 1 | Z10: 1 | AA10: 0 | AB10: 4 | AC10: Undecided | AD10: Undecided | AE10: Undecided | AF10: NA | AG10: NA | AH10: NA | AI10: 1 | AJ10: 1 | AK10: 1 | AL10: 1 | AM10: 1 | AN10: 1 | AO10: NA | AP10: NA | AQ10: NA | AR10: 1 | AS10: 1 | AT10: 1 | AU10: NA | AV10: NA | AW10: NA | AX10: Undecided | AY10: Undecided | AZ10: Undecided | BA10: 1 | BB10: 1 | BC10: 1 | BD10: 1 | BE10: 1 | BF10: 1 | BG10: 1 | BH10: 1 | BI10: 1 | BJ10: 0 | BK10: 0 | BL10: 0 | BM10: 0 | BN10: 0 | BO10: 0 | BP10: 1 | BQ10: 1 | BR10: 1 | BS10: 0 | BT10: 0 | BU10: 0 | BV10: 1D | BW10: 0 | BX10: 0 | BY10: 0 | BZ10: 0 | CA10: 0 | CB10: 0 | CC10: 0 | CD10: 0 | CE10: 0 | CF10: 0
A11: 2 | B11: 1 | C11: G | D11: 1 | E11: 2 | F11: E | G11: Undecided | H11: Undecided | I11: Undecided | J11: Undecided | K11: 1 | L11: 1 | M11: 1 | N11: Undecided | O11: 1 | P11: 1 | Q11: 1 | R11: 1 | S11: 1 | T11: 4 | U11: Undecided | V11: 1 | W11: 1 | X11: 1 | Y11: 1 | Z11: 1 | AA11: 0 | AB11: 4 | AC11: Undecided | AD11: Undecided | AE11: Undecided | AF11: NA | AG11: NA | AH11: NA | AI11: 1 | AJ11: 1 | AK11: 1 | AL11: 1 | AM11: 1 | AN11: 1 | AO11: NA | AP11: NA | AQ11: NA | AR11: 1 | AS11: 1 | AT11: 1 | AU11: NA | AV11: NA | AW11: NA | AX11: Undecided | AY11: Undecided | AZ11: Undecided | BA11: 1 | BB11: 1 | BC11: 1 | BD11: 1 | BE11: 1 | BF11: 1 | BG11: 1 | BH11: 1 | BI11: 1 | BJ11: 0 | BK11: 0 | BL11: 0 | BM11: 0 | BN11: 0 | BO11: 0 | BP11: 1 | BQ11: 1 | BR11: 1 | BS11: 0 | BT11: 0 | BU11: 0 | BV11: 1E | BW11: 0 | BX11: 0 | BY11: 0 | BZ11: 0 | CA11: 0 | CB11: 0 | CC11: 0 | CD11: 0 | CE11: 0 | CF11: 0
A12: 3 | B12: 1 | C12: G | D12: 1 | E12: 3 | F12: A | G12: Undecided | H12: Undecided | I12: Accept | J12: Accept | K12: 0 | L12: 0 | M12: 1 | N12: Reject | O12: 0 | P12: 0 | Q12: 0 | R12: 2 | S12: 0 | T12: 4 | U12: Reject | V12: 0 | W12: 0 | X12: 0 | Y12: 0 | Z12: 3 | AA12: 0 | AB12: 3 | AC12: Undecided | AD12: Undecided | AE12: Accept | AF12: Accept | AG12: Accept | AH12: Accept | AI12: 0 | AJ12: 0 | AK12: 1 | AL12: 0 | AM12: 0 | AN12: 0 | AO12: 0 | AP12: 0 | AQ12: 0 | AR12: 0 | AS12: 0 | AT12: 0 | AU12: 0 | AV12: 0 | AW12: 0 | AX12: Undecided | AY12: Accept | AZ12: Accept | BA12: 0 | BB12: 1 | BC12: 1 | BD12: 0 | BE12: 0 | BF12: 0 | BG12: 0 | BH12: 0 | BI12: 0 | BJ12: 1 | BK12: 0 | BL12: 1 | BM12: 1 | BN12: 1 | BO12: 0 | BP12: 0 | BQ12: 0 | BR12: 0 | BS12: 1 | BT12: 0 | BU12: 0 | BV12: 1A | BW12: 0 | BX12: 0 | BY12: 0 | BZ12: 0 | CA12: 0 | CB12: 0 | CC12: 0 | CD12: 0 | CE12: 0 | CF12: 0
A13: 3 | B13: 1 | C13: G | D13: 1 | E13: 3 | F13: B | G13: Undecided | H13: Undecided | I13: Reject | J13: Reject | K13: 0 | L13: 0 | M13: 1 | N13: Reject | O13: 0 | P13: 0 | Q13: 1 | R13: 2 | S13: 1 | T13: 4 | U13: Reject | V13: 0 | W13: 0 | X13: 1 | Y13: 1 | Z13: 3 | AA13: 0 | AB13: 3 | AC13: Undecided | AD13: Undecided | AE13: Reject | AF13: Reject | AG13: Reject | AH13: Reject | AI13: 0 | AJ13: 0 | AK13: 1 | AL13: 0 | AM13: 0 | AN13: 1 | AO13: 1 | AP13: 1 | AQ13: 1 | AR13: 0 | AS13: 0 | AT13: 1 | AU13: 1 | AV13: 1 | AW13: 1 | AX13: Undecided | AY13: Reject | AZ13: Reject | BA13: 0 | BB13: 1 | BC13: 1 | BD13: 0 | BE13: 1 | BF13: 1 | BG13: 0 | BH13: 1 | BI13: 1 | BJ13: 1 | BK13: 0 | BL13: 1 | BM13: 1 | BN13: 1 | BO13: 0 | BP13: 0 | BQ13: 0 | BR13: 0 | BS13: 1 | BT13: 0 | BU13: 0 | BV13: 1B | BW13: 0 | BX13: 0 | BY13: 0 | BZ13: 0 | CA13: 0 | CB13: 0 | CC13: 0 | CD13: 0 | CE13: 0 | CF13: 0
A14: 3 | B14: 1 | C14: G | D14: 1 | E14: 3 | F14: C | G14: Undecided | H14: Undecided | I14: Undecided | J14: Undecided | K14: 1 | L14: 1 | M14: 1 | N14: Undecided | O14: 1 | P14: 1 | Q14: 1 | R14: 2 | S14: 1 | T14: 4 | U14: Undecided | V14: 1 | W14: 1 | X14: 1 | Y14: 1 | Z14: 3 | AA14: 0 | AB14: 3 | AC14: Undecided | AD14: Undecided | AE14: Undecided | AF14: Accept | AG14: Accept | AH14: Accept | AI14: 1 | AJ14: 1 | AK14: 1 | AL14: 1 | AM14: 1 | AN14: 1 | AO14: 0 | AP14: 0 | AQ14: 0 | AR14: 1 | AS14: 1 | AT14: 1 | AU14: 0 | AV14: 0 | AW14: 0 | AX14: Undecided | AY14: Undecided | AZ14: Undecided | BA14: 1 | BB14: 1 | BC14: 1 | BD14: 1 | BE14: 1 | BF14: 1 | BG14: 1 | BH14: 1 | BI14: 1 | BJ14: 0 | BK14: 0 | BL14: 0 | BM14: 0 | BN14: 0 | BO14: 0 | BP14: 1 | BQ14: 1 | BR14: 1 | BS14: 0 | BT14: 0 | BU14: 0 | BV14: 1C | BW14: 0 | BX14: 0 | BY14: 0 | BZ14: 0 | CA14: 0 | CB14: 0 | CC14: 0 | CD14: 0 | CE14: 0 | CF14: 0
A15: 3 | B15: 1 | C15: G | D15: 1 | E15: 3 | F15: D | G15: Undecided | H15: Undecided | I15: Undecided | J15: Undecided | K15: 1 | L15: 1 | M15: 1 | N15: Undecided | O15: 1 | P15: 1 | Q15: 1 | R15: 2 | S15: 1 | T15: 4 | U15: Undecided | V15: 1 | W15: 1 | X15: 1 | Y15: 1 | Z15: 3 | AA15: 0 | AB15: 3 | AC15: Undecided | AD15: Undecided | AE15: Undecided | AF15: Accept | AG15: Accept | AH15: Accept | AI15: 1 | AJ15: 1 | AK15: 1 | AL15: 1 | AM15: 1 | AN15: 1 | AO15: 0 | AP15: 0 | AQ15: 0 | AR15: 1 | AS15: 1 | AT15: 1 | AU15: 0 | AV15: 0 | AW15: 0 | AX15: Undecided | AY15: Undecided | AZ15: Undecided | BA15: 1 | BB15: 1 | BC15: 1 | BD15: 1 | BE15: 1 | BF15: 1 | BG15: 1 | BH15: 1 | BI15: 1 | BJ15: 0 | BK15: 0 | BL15: 0 | BM15: 0 | BN15: 0 | BO15: 0 | BP15: 1 | BQ15: 1 | BR15: 1 | BS15: 0 | BT15: 0 | BU15: 0 | BV15: 1D | BW15: 0 | BX15: 0 | BY15: 0 | BZ15: 0 | CA15: 0 | CB15: 0 | CC15: 0 | CD15: 0 | CE15: 0 | CF15: 0
A16: 3 | B16: 1 | C16: G | D16: 1 | E16: 3 | F16: E | G16: Undecided | H16: Undecided | I16: Undecided | J16: Undecided | K16: 1 | L16: 1 | M16: 1 | N16: Undecided | O16: 1 | P16: 1 | Q16: 1 | R16: 2 | S16: 1 | T16: 4 | U16: Undecided | V16: 1 | W16: 1 | X16: 1 | Y16: 1 | Z16: 3 | AA16: 0 | AB16: 3 | AC16: Undecided | AD16: Undecided | AE16: Undecided | AF16: Accept | AG16: Accept | AH16: Accept | AI16: 1 | AJ16: 1 | AK16: 1 | AL16: 1 | AM16: 1 | AN16: 1 | AO16: 0 | AP16: 0 | AQ16: 0 | AR16: 1 | AS16: 1 | AT16: 1 | AU16: 0 | AV16: 0 | AW16: 0 | AX16: Undecided | AY16: Undecided | AZ16: Undecided | BA16: 1 | BB16: 1 | BC16: 1 | BD16: 1 | BE16: 1 | BF16: 1 | BG16: 1 | BH16: 1 | BI16: 1 | BJ16: 0 | BK16: 0 | BL16: 0 | BM16: 0 | BN16: 0 | BO16: 0 | BP16: 1 | BQ16: 1 | BR16: 1 | BS16: 0 | BT16: 0 | BU16: 0 | BV16: 1E | BW16: 0 | BX16: 0 | BY16: 0 | BZ16: 0 | CA16: 0 | CB16: 0 | CC16: 0 | CD16: 0 | CE16: 0 | CF16: 0
A17: 4 | B17: 1 | C17: G | D17: 1 | E17: 4 | F17: A | G17: Undecided | H17: Undecided | I17: Accept | J17: Accept | K17: 0 | L17: 0 | M17: 1 | N17: Undecided | O17: 1 | P17: 1 | Q17: 0 | R17: 1 | S17: 0 | T17: 2 | U17: Accept | V17: 0 | W17: 0 | X17: 1 | Y17: 1 | Z17: 2 | AA17: 1 | AB17: 2 | AC17: Undecided | AD17: Undecided | AE17: Accept | AF17: Undecided | AG17: Accept | AH17: Accept | AI17: 0 | AJ17: 0 | AK17: 1 | AL17: 1 | AM17: 1 | AN17: 0 | AO17: 1 | AP17: 0 | AQ17: 0 | AR17: 0 | AS17: 0 | AT17: 1 | AU17: 0 | AV17: 1 | AW17: 1 | AX17: Undecided | AY17: Accept | AZ17: Accept | BA17: 0 | BB17: 1 | BC17: 1 | BD17: 1 | BE17: 0 | BF17: 0 | BG17: 0 | BH17: 1 | BI17: 1 | BJ17: 1 | BK17: 0 | BL17: 1 | BM17: 1 | BN17: 1 | BO17: 0 | BP17: 1 | BQ17: 0 | BR17: 0 | BS17: 1 | BT17: 0 | BU17: 0 | BV17: 1A | BW17: 0 | BX17: 0 | BY17: 0 | BZ17: 0 | CA17: 0 | CB17: 0 | CC17: 0 | CD17: 0 | CE17: 0 | CF17: 0
A18: 4 | B18: 1 | C18: G | D18: 1 | E18: 4 | F18: B | G18: Undecided | H18: Undecided | I18: Reject | J18: Reject | K18: 0 | L18: 0 | M18: 1 | N18: Reject | O18: 0 | P18: 0 | Q18: 1 | R18: 1 | S18: 1 | T18: 2 | U18: Reject | V18: 0 | W18: 0 | X18: 1 | Y18: 1 | Z18: 2 | AA18: 0 | AB18: 2 | AC18: Undecided | AD18: Undecided | AE18: Reject | AF18: Undecided | AG18: Reject | AH18: Reject | AI18: 0 | AJ18: 0 | AK18: 1 | AL18: 0 | AM18: 0 | AN18: 1 | AO18: 0 | AP18: 1 | AQ18: 1 | AR18: 0 | AS18: 0 | AT18: 1 | AU18: 0 | AV18: 1 | AW18: 1 | AX18: Undecided | AY18: Reject | AZ18: Reject | BA18: 0 | BB18: 1 | BC18: 1 | BD18: 0 | BE18: 1 | BF18: 1 | BG18: 0 | BH18: 1 | BI18: 1 | BJ18: 1 | BK18: 0 | BL18: 1 | BM18: 1 | BN18: 1 | BO18: 0 | BP18: 1 | BQ18: 0 | BR18: 0 | BS18: 1 | BT18: 0 | BU18: 0 | BV18: 1B | BW18: 0 | BX18: 0 | BY18: 0 | BZ18: 0 | CA18: 0 | CB18: 0 | CC18: 0 | CD18: 0 | CE18: 0 | CF18: 0
A19: 4 | B19: 1 | C19: G | D19: 1 | E19: 4 | F19: C | G19: Undecided | H19: Undecided | I19: Undecided | J19: Undecided | K19: 1 | L19: 1 | M19: 1 | N19: Reject | O19: 0 | P19: 0 | Q19: 0 | R19: 1 | S19: 0 | T19: 2 | U19: Reject | V19: 0 | W19: 0 | X19: 0 | Y19: 0 | Z19: 2 | AA19: 0 | AB19: 2 | AC19: Undecided | AD19: Undecided | AE19: Undecided | AF19: Undecided | AG19: Undecided | AH19: Undecided | AI19: 1 | AJ19: 1 | AK19: 1 | AL19: 0 | AM19: 0 | AN19: 0 | AO19: 0 | AP19: 0 | AQ19: 0 | AR19: 0 | AS19: 0 | AT19: 0 | AU19: 0 | AV19: 0 | AW19: 0 | AX19: Undecided | AY19: Undecided | AZ19: Undecided | BA19: 1 | BB19: 1 | BC19: 1 | BD19: 0 | BE19: 0 | BF19: 0 | BG19: 0 | BH19: 0 | BI19: 0 | BJ19: 0 | BK19: 0 | BL19: 0 | BM19: 0 | BN19: 0 | BO19: 0 | BP19: 0 | BQ19: 0 | BR19: 0 | BS19: 0 | BT19: 0 | BU19: 0 | BV19: 1C | BW19: 0 | BX19: 0 | BY19: 0 | BZ19: 0 | CA19: 0 | CB19: 0 | CC19: 0 | CD19: 0 | CE19: 0 | CF19: 0
A20: 4 | B20: 1 | C20: G | D20: 1 | E20: 4 | F20: D | G20: Undecided | H20: Undecided | I20: Undecided | J20: Undecided | K20: 1 | L20: 1 | M20: 1 | N20: Reject | O20: 0 | P20: 0 | Q20: 0 | R20: 1 | S20: 0 | T20: 2 | U20: Reject | V20: 0 | W20: 0 | X20: 0 | Y20: 0 | Z20: 2 | AA20: 0 | AB20: 2 | AC20: Undecided | AD20: Undecided | AE20: Undecided | AF20: Undecided | AG20: Undecided | AH20: Undecided | AI20: 1 | AJ20: 1 | AK20: 1 | AL20: 0 | AM20: 0 | AN20: 0 | AO20: 0 | AP20: 0 | AQ20: 0 | AR20: 0 | AS20: 0 | AT20: 0 | AU20: 0 | AV20: 0 | AW20: 0 | AX20: Undecided | AY20: Undecided | AZ20: Undecided | BA20: 1 | BB20: 1 | BC20: 1 | BD20: 0 | BE20: 0 | BF20: 0 | BG20: 0 | BH20: 0 | BI20: 0 | BJ20: 0 | BK20: 0 | BL20: 0 | BM20: 0 | BN20: 0 | BO20: 0 | BP20: 0 | BQ20: 0 | BR20: 0 | BS20: 0 | BT20: 0 | BU20: 0 | BV20: 1D | BW20: 0 | BX20: 0 | BY20: 0 | BZ20: 0 | CA20: 0 | CB20: 0 | CC20: 0 | CD20: 0 | CE20: 0 | CF20: 0
A21: 4 | B21: 1 | C21: G | D21: 1 | E21: 4 | F21: E | G21: Undecided | H21: Undecided | I21: Undecided | J21: Undecided | K21: 1 | L21: 1 | M21: 1 | N21: Reject | O21: 0 | P21: 0 | Q21: 0 | R21: 1 | S21: 0 | T21: 2 | U21: Reject | V21: 0 | W21: 0 | X21: 0 | Y21: 0 | Z21: 2 | AA21: 0 | AB21: 2 | AC21: Undecided | AD21: Undecided | AE21: Undecided | AF21: Undecided | AG21: Undecided | AH21: Undecided | AI21: 1 | AJ21: 1 | AK21: 1 | AL21: 0 | AM21: 0 | AN21: 0 | AO21: 0 | AP21: 0 | AQ21: 0 | AR21: 0 | AS21: 0 | AT21: 0 | AU21: 0 | AV21: 0 | AW21: 0 | AX21: Undecided | AY21: Undecided | AZ21: Undecided | BA21: 1 | BB21: 1 | BC21: 1 | BD21: 0 | BE21: 0 | BF21: 0 | BG21: 0 | BH21: 0 | BI21: 0 | BJ21: 0 | BK21: 0 | BL21: 0 | BM21: 0 | BN21: 0 | BO21: 0 | BP21: 0 | BQ21: 0 | BR21: 0 | BS21: 0 | BT21: 0 | BU21: 0 | BV21: 1E | BW21: 0 | BX21: 0 | BY21: 0 | BZ21: 0 | CA21: 0 | CB21: 0 | CC21: 0 | CD21: 0 | CE21: 0 | CF21: 0
A22: 5 | B22: 1 | C22: G | D22: 1 | E22: 5 | F22: A | G22: Undecided | H22: Undecided | I22: Accept | J22: Accept | K22: 0 | L22: 0 | M22: 1 | N22: Reject | O22: 0 | P22: 0 | Q22: 0 | R22: 1 | S22: 0 | T22: 2 | U22: Undecided | V22: 1 | W22: 1 | X22: 0 | Y22: 0 | Z22: 2 | AA22: 1 | AB22: 1 | AC22: Undecided | AD22: Undecided | AE22: Accept | AF22: Undecided | AG22: Undecided | AH22: Accept | AI22: 0 | AJ22: 0 | AK22: 1 | AL22: 0 | AM22: 0 | AN22: 0 | AO22: 0 | AP22: 0 | AQ22: 0 | AR22: 1 | AS22: 1 | AT22: 0 | AU22: 1 | AV22: 1 | AW22: 0 | AX22: Undecided | AY22: Accept | AZ22: Accept | BA22: 0 | BB22: 1 | BC22: 1 | BD22: 0 | BE22: 0 | BF22: 0 | BG22: 1 | BH22: 0 | BI22: 0 | BJ22: 1 | BK22: 0 | BL22: 1 | BM22: 1 | BN22: 1 | BO22: 0 | BP22: 1 | BQ22: 1 | BR22: 0 | BS22: 1 | BT22: 0 | BU22: 0 | BV22: 1A | BW22: 0 | BX22: 0 | BY22: 0 | BZ22: 0 | CA22: 0 | CB22: 0 | CC22: 0 | CD22: 0 | CE22: 0 | CF22: 0
A23: 5 | B23: 1 | C23: G | D23: 1 | E23: 5 | F23: B | G23: Undecided | H23: Undecided | I23: Reject | J23: Reject | K23: 0 | L23: 0 | M23: 1 | N23: Reject | O23: 0 | P23: 0 | Q23: 1 | R23: 1 | S23: 1 | T23: 2 | U23: Reject | V23: 0 | W23: 0 | X23: 1 | Y23: 1 | Z23: 2 | AA23: 0 | AB23: 1 | AC23: Undecided | AD23: Undecided | AE23: Reject | AF23: Undecided | AG23: Undecided | AH23: Reject | AI23: 0 | AJ23: 0 | AK23: 1 | AL23: 0 | AM23: 0 | AN23: 1 | AO23: 0 | AP23: 0 | AQ23: 1 | AR23: 0 | AS23: 0 | AT23: 1 | AU23: 0 | AV23: 0 | AW23: 1 | AX23: Undecided | AY23: Reject | AZ23: Reject | BA23: 0 | BB23: 1 | BC23: 1 | BD23: 0 | BE23: 1 | BF23: 1 | BG23: 0 | BH23: 1 | BI23: 1 | BJ23: 1 | BK23: 0 | BL23: 1 | BM23: 1 | BN23: 1 | BO23: 0 | BP23: 1 | BQ23: 1 | BR23: 0 | BS23: 1 | BT23: 0 | BU23: 0 | BV23: 1B | BW23: 0 | BX23: 0 | BY23: 0 | BZ23: 0 | CA23: 0 | CB23: 0 | CC23: 0 | CD23: 0 | CE23: 0 | CF23: 0
... A491: 128 | B491: 35 | C491: G | D491: 5 | E491: 3 | F491: E | G491: Undecided | H491: Undecided | I491: Undecided | J491: Undecided | K491: 1 | L491: 1 | M491: 1 | N491: Accept | O491: 0 | P491: 0 | Q491: 0 | R491: 4 | S491: 0 | T491: 3 | U491: Accept | V491: 0 | W491: 0 | X491: 0 | Y491: 0 | Z491: 2 | AA491: 0 | AB491: 3 | AC491: Accept | AD491: Accept | AE491: Accept | AF491: Accept | AG491: Accept | AH491: Accept | AI491: 0 | AJ491: 0 | AK491: 0 | AL491: 1 | AM491: 1 | AN491: 1 | AO491: 1 | AP491: 1 | AQ491: 1 | AR491: 1 | AS491: 1 | AT491: 1 | AU491: 1 | AV491: 1 | AW491: 1 | AX491: Undecided | AY491: Undecided | AZ491: Undecided | BA491: 1 | BB491: 1 | BC491: 1 | BD491: 0 | BE491: 0 | BF491: 0 | BG491: 0 | BH491: 0 | BI491: 0 | BJ491: 0 | BK491: 0 | BL491: 0 | BM491: 1 | BN491: 1 | BO491: 1 | BP491: 1 | BQ491: 1 | BR491: 1 | BS491: 0 | BT491: 0 | BU491: 0 | BV491: 35E | BW491: 0 | BX491: 0 | BY491: 0 | BZ491: 0 | CA491: 0 | CB491: 0 | CC491: 0 | CD491: 0 | CE491: 0 | CF491: 0
A492: 129 | B492: 35 | C492: G | D492: 5 | E492: 4 | F492: A | G492: Undecided | H492: Undecided | I492: Accept | J492: Accept | K492: 0 | L492: 0 | M492: 1 | N492: Undecided | O492: 1 | P492: 1 | Q492: 0 | R492: NA | S492: 0 | T492: 3 | U492: Accept | V492: 0 | W492: 0 | X492: 1 | Y492: 1 | Z492: 3 | AA492: 1 | AB492: 3 | AC492: Accept | AD492: Accept | AE492: Accept | AF492: Accept | AG492: Accept | AH492: Accept | AI492: 1 | AJ492: 1 | AK492: 1 | AL492: 0 | AM492: 0 | AN492: 0 | AO492: 0 | AP492: 0 | AQ492: 0 | AR492: 1 | AS492: 1 | AT492: 1 | AU492: 1 | AV492: 1 | AW492: 1 | AX492: Undecided | AY492: Accept | AZ492: Accept | BA492: 0 | BB492: 1 | BC492: 1 | BD492: 1 | BE492: 0 | BF492: 0 | BG492: 0 | BH492: 1 | BI492: 1 | BJ492: 1 | BK492: 0 | BL492: 1 | BM492: 0 | BN492: 0 | BO492: 0 | BP492: 0 | BQ492: 0 | BR492: 0 | BS492: 1 | BT492: 0 | BU492: 0 | BV492: 35A | BW492: 0 | BX492: 0 | BY492: 0 | BZ492: 0 | CA492: 0 | CB492: 0 | CC492: 0 | CD492: 0 | CE492: 0 | CF492: 0
A493: 129 | B493: 35 | C493: G | D493: 5 | E493: 4 | F493: B | G493: Undecided | H493: Undecided | I493: Reject | J493: Undecided | K493: 1 | L493: 1 | M493: 0 | N493: Accept | O493: 0 | P493: 0 | Q493: 0 | R493: NA | S493: 0 | T493: 3 | U493: Undecided | V493: 1 | W493: 1 | X493: 0 | Y493: 1 | Z493: 3 | AA493: 1 | AB493: 3 | AC493: Reject | AD493: Reject | AE493: Reject | AF493: Reject | AG493: Reject | AH493: Reject | AI493: 0 | AJ493: 0 | AK493: 0 | AL493: 0 | AM493: 0 | AN493: 0 | AO493: 0 | AP493: 0 | AQ493: 0 | AR493: 0 | AS493: 0 | AT493: 0 | AU493: 0 | AV493: 0 | AW493: 0 | AX493: Undecided | AY493: Reject | AZ493: Reject | BA493: 1 | BB493: 0 | BC493: 0 | BD493: 0 | BE493: 0 | BF493: 0 | BG493: 1 | BH493: 0 | BI493: 0 | BJ493: 1 | BK493: 0 | BL493: 1 | BM493: 0 | BN493: 0 | BO493: 0 | BP493: 0 | BQ493: 0 | BR493: 0 | BS493: 1 | BT493: 0 | BU493: 0 | BV493: 35B | BW493: 0 | BX493: 0 | BY493: 0 | BZ493: 0 | CA493: 0 | CB493: 0 | CC493: 0 | CD493: 0 | CE493: 0 | CF493: 0
A494: 129 | B494: 35 | C494: G | D494: 5 | E494: 4 | F494: C | G494: Undecided | H494: Undecided | I494: Undecided | J494: Accept | K494: 0 | L494: 0 | M494: 0 | N494: Undecided | O494: 1 | P494: 1 | Q494: 1 | R494: NA | S494: 0 | T494: 3 | U494: Accept | V494: 0 | W494: 0 | X494: 0 | Y494: 1 | Z494: 3 | AA494: 1 | AB494: 3 | AC494: Accept | AD494: Accept | AE494: Accept | AF494: Accept | AG494: Accept | AH494: Accept | AI494: 1 | AJ494: 1 | AK494: 1 | AL494: 0 | AM494: 0 | AN494: 0 | AO494: 0 | AP494: 0 | AQ494: 0 | AR494: 1 | AS494: 1 | AT494: 1 | AU494: 1 | AV494: 1 | AW494: 1 | AX494: Undecided | AY494: Undecided | AZ494: Undecided | BA494: 0 | BB494: 0 | BC494: 0 | BD494: 1 | BE494: 1 | BF494: 1 | BG494: 0 | BH494: 0 | BI494: 0 | BJ494: 0 | BK494: 0 | BL494: 0 | BM494: 1 | BN494: 1 | BO494: 1 | BP494: 1 | BQ494: 1 | BR494: 1 | BS494: 0 | BT494: 0 | BU494: 0 | BV494: 35C | BW494: 0 | BX494: 0 | BY494: 0 | BZ494: 0 | CA494: 0 | CB494: 0 | CC494: 0 | CD494: 0 | CE494: 0 | CF494: 0
A495: 129 | B495: 35 | C495: G | D495: 5 | E495: 4 | F495: D | G495: Undecided | H495: Undecided | I495: Undecided | J495: Reject | K495: 0 | L495: 0 | M495: 0 | N495: Reject | O495: 0 | P495: 0 | Q495: 0 | R495: NA | S495: 1 | T495: 3 | U495: Reject | V495: 0 | W495: 0 | X495: 0 | Y495: 1 | Z495: 3 | AA495: 0 | AB495: 3 | AC495: Reject | AD495: Reject | AE495: Reject | AF495: Accept | AG495: Accept | AH495: Accept | AI495: 1 | AJ495: 1 | AK495: 1 | AL495: 1 | AM495: 1 | AN495: 1 | AO495: 0 | AP495: 0 | AQ495: 0 | AR495: 1 | AS495: 1 | AT495: 1 | AU495: 0 | AV495: 0 | AW495: 0 | AX495: Undecided | AY495: Undecided | AZ495: Undecided | BA495: 0 | BB495: 0 | BC495: 0 | BD495: 0 | BE495: 0 | BF495: 0 | BG495: 0 | BH495: 0 | BI495: 0 | BJ495: 0 | BK495: 0 | BL495: 0 | BM495: 1 | BN495: 1 | BO495: 1 | BP495: 1 | BQ495: 1 | BR495: 1 | BS495: 0 | BT495: 0 | BU495: 0 | BV495: 35D | BW495: 0 | BX495: 0 | BY495: 0 | BZ495: 0 | CA495: 0 | CB495: 0 | CC495: 0 | CD495: 0 | CE495: 0 | CF495: 0
A496: 129 | B496: 35 | C496: G | D496: 5 | E496: 4 | F496: E | G496: Undecided | H496: Undecided | I496: Undecided | J496: Undecided | K496: 1 | L496: 1 | M496: 1 | N496: Reject | O496: 0 | P496: 0 | Q496: 0 | R496: NA | S496: 0 | T496: 3 | U496: Undecided | V496: 1 | W496: 1 | X496: 1 | Y496: 1 | Z496: 3 | AA496: 1 | AB496: 3 | AC496: Accept | AD496: Accept | AE496: Accept | AF496: Reject | AG496: Reject | AH496: Reject | AI496: 0 | AJ496: 0 | AK496: 0 | AL496: 0 | AM496: 0 | AN496: 0 | AO496: 1 | AP496: 1 | AQ496: 1 | AR496: 0 | AS496: 0 | AT496: 0 | AU496: 0 | AV496: 0 | AW496: 0 | AX496: Undecided | AY496: Undecided | AZ496: Undecided | BA496: 1 | BB496: 1 | BC496: 1 | BD496: 0 | BE496: 0 | BF496: 0 | BG496: 1 | BH496: 1 | BI496: 1 | BJ496: 0 | BK496: 0 | BL496: 0 | BM496: 1 | BN496: 1 | BO496: 1 | BP496: 1 | BQ496: 1 | BR496: 1 | BS496: 0 | BT496: 0 | BU496: 0 | BV496: 35E | BW496: 0 | BX496: 0 | BY496: 0 | BZ496: 0 | CA496: 0 | CB496: 0 | CC496: 0 | CD496: 0 | CE496: 0 | CF496: 0
A497: 130 | B497: 35 | C497: G | D497: 5 | E497: 5 | F497: A | G497: Undecided | H497: Undecided | I497: Accept | J497: Accept | K497: 0 | L497: 0 | M497: 1 | N497: Undecided | O497: 1 | P497: 1 | Q497: 0 | R497: 2 | S497: 0 | T497: 3 | U497: Accept | V497: 0 | W497: 0 | X497: 1 | Y497: 1 | Z497: 3 | AA497: 1 | AB497: 2 | AC497: Accept | AD497: Accept | AE497: Accept | AF497: Accept | AG497: Accept | AH497: Accept | AI497: 1 | AJ497: 1 | AK497: 1 | AL497: 0 | AM497: 0 | AN497: 0 | AO497: 0 | AP497: 0 | AQ497: 0 | AR497: 1 | AS497: 1 | AT497: 1 | AU497: 1 | AV497: 1 | AW497: 1 | AX497: Undecided | AY497: Accept | AZ497: Accept | BA497: 0 | BB497: 1 | BC497: 1 | BD497: 1 | BE497: 0 | BF497: 0 | BG497: 0 | BH497: 1 | BI497: 1 | BJ497: 1 | BK497: 0 | BL497: 1 | BM497: 0 | BN497: 0 | BO497: 0 | BP497: 0 | BQ497: 0 | BR497: 0 | BS497: 1 | BT497: 0 | BU497: 0 | BV497: 35A | BW497: 0 | BX497: 0 | BY497: 0 | BZ497: 0 | CA497: 0 | CB497: 0 | CC497: 0 | CD497: 0 | CE497: 0 | CF497: 0
A498: 130 | B498: 35 | C498: G | D498: 5 | E498: 5 | F498: B | G498: Undecided | H498: Undecided | I498: Reject | J498: Undecided | K498: 1 | L498: 1 | M498: 0 | N498: Undecided | O498: 1 | P498: 1 | Q498: 0 | R498: 2 | S498: 1 | T498: 3 | U498: Undecided | V498: 1 | W498: 1 | X498: 0 | Y498: 1 | Z498: 3 | AA498: 0 | AB498: 2 | AC498: Reject | AD498: Reject | AE498: Reject | AF498: Reject | AG498: Reject | AH498: Reject | AI498: 0 | AJ498: 0 | AK498: 0 | AL498: 0 | AM498: 0 | AN498: 0 | AO498: 0 | AP498: 0 | AQ498: 0 | AR498: 0 | AS498: 0 | AT498: 0 | AU498: 0 | AV498: 0 | AW498: 0 | AX498: Undecided | AY498: Reject | AZ498: Reject | BA498: 1 | BB498: 0 | BC498: 0 | BD498: 1 | BE498: 0 | BF498: 0 | BG498: 1 | BH498: 0 | BI498: 0 | BJ498: 1 | BK498: 0 | BL498: 1 | BM498: 0 | BN498: 0 | BO498: 0 | BP498: 0 | BQ498: 0 | BR498: 0 | BS498: 1 | BT498: 0 | BU498: 0 | BV498: 35B | BW498: 0 | BX498: 0 | BY498: 0 | BZ498: 0 | CA498: 0 | CB498: 0 | CC498: 0 | CD498: 0 | CE498: 0 | CF498: 0
A499: 130 | B499: 35 | C499: G | D499: 5 | E499: 5 | F499: C | G499: Undecided | H499: Undecided | I499: Undecided | J499: Accept | K499: 0 | L499: 0 | M499: 0 | N499: Reject | O499: 0 | P499: 0 | Q499: 0 | R499: 2 | S499: 0 | T499: 3 | U499: Undecided | V499: 1 | W499: 1 | X499: 1 | Y499: 0 | Z499: 3 | AA499: 1 | AB499: 2 | AC499: Accept | AD499: Accept | AE499: Accept | AF499: Accept | AG499: Accept | AH499: Accept | AI499: 1 | AJ499: 1 | AK499: 1 | AL499: 0 | AM499: 0 | AN499: 0 | AO499: 0 | AP499: 0 | AQ499: 0 | AR499: 0 | AS499: 0 | AT499: 0 | AU499: 0 | AV499: 0 | AW499: 0 | AX499: Undecided | AY499: Undecided | AZ499: Undecided | BA499: 0 | BB499: 0 | BC499: 0 | BD499: 0 | BE499: 0 | BF499: 0 | BG499: 1 | BH499: 1 | BI499: 1 | BJ499: 0 | BK499: 0 | BL499: 0 | BM499: 1 | BN499: 1 | BO499: 1 | BP499: 1 | BQ499: 1 | BR499: 1 | BS499: 0 | BT499: 0 | BU499: 0 | BV499: 35C | BW499: 0 | BX499: 0 | BY499: 0 | BZ499: 0 | CA499: 0 | CB499: 0 | CC499: 0 | CD499: 0 | CE499: 0 | CF499: 0
A500: 130 | B500: 35 | C500: G | D500: 5 | E500: 5 | F500: D | G500: Undecided | H500: Undecided | I500: Undecided | J500: Reject | K500: 0 | L500: 0 | M500: 0 | N500: Reject | O500: 0 | P500: 0 | Q500: 0 | R500: 2 | S500: 1 | T500: 3 | U500: Reject | V500: 0 | W500: 0 | X500: 0 | Y500: 1 | Z500: 3 | AA500: 0 | AB500: 2 | AC500: Reject | AD500: Reject | AE500: Reject | AF500: Reject | AG500: Reject | AH500: Reject | AI500: 1 | AJ500: 1 | AK500: 1 | AL500: 1 | AM500: 1 | AN500: 1 | AO500: 1 | AP500: 1 | AQ500: 1 | AR500: 1 | AS500: 1 | AT500: 1 | AU500: 1 | AV500: 1 | AW500: 1 | AX500: Undecided | AY500: Undecided | AZ500: Undecided | BA500: 0 | BB500: 0 | BC500: 0 | BD500: 0 | BE500: 0 | BF500: 0 | BG500: 0 | BH500: 0 | BI500: 0 | BJ500: 0 | BK500: 0 | BL500: 0 | BM500: 1 | BN500: 1 | BO500: 1 | BP500: 1 | BQ500: 1 | BR500: 1 | BS500: 0 | BT500: 0 | BU500: 0 | BV500: 35D | BW500: 0 | BX500: 0 | BY500: 0 | BZ500: 0 | CA500: 0 | CB500: 0 | CC500: 0 | CD500: 0 | CE500: 0 | CF500: 0
A501: 130 | B501: 35 | C501: G | D501: 5 | E501: 5 | F501: E | G501: Undecided | H501: Undecided | I501: Undecided | J501: Undecided | K501: 1 | L501: 1 | M501: 1 | N501: Accept | O501: 0 | P501: 0 | Q501: 0 | R501: 2 | S501: 0 | T501: 3 | U501: Accept | V501: 0 | W501: 0 | X501: 0 | Y501: 0 | Z501: 3 | AA501: 0 | AB501: 2 | AC501: Accept | AD501: Accept | AE501: Accept | AF501: Accept | AG501: Accept | AH501: Accept | AI501: 0 | AJ501: 0 | AK501: 0 | AL501: 1 | AM501: 1 | AN501: 1 | AO501: 1 | AP501: 1 | AQ501: 1 | AR501: 1 | AS501: 1 | AT501: 1 | AU501: 1 | AV501: 1 | AW501: 1 | AX501: Undecided | AY501: Undecided | AZ501: Undecided | BA501: 1 | BB501: 1 | BC501: 1 | BD501: 0 | BE501: 0 | BF501: 0 | BG501: 0 | BH501: 0 | BI501: 0 | BJ501: 0 | BK501: 0 | BL501: 0 | BM501: 1 | BN501: 1 | BO501: 1 | BP501: 1 | BQ501: 1 | BR501: 1 | BS501: 0 | BT501: 0 | BU501: 0 | BV501: 35E | BW501: 0 | BX501: 0 | BY501: 0 | BZ501: 0 | CA501: 0 | CB501: 0 | CC501: 0 | CD501: 0 | CE501: 0 | CF501: 0

Sheet Attacks
A1: ID | B1: ATTACK
A2: ="p"&PART_A!A2&"_version"&PART_A!C2 -> p1_versionG | B2: =IF(PART_A!J2="Attack","att("&LOWER(LEFT(PART_A!F2,FIND("_",PART_A!F2)-1))&","&LOWER(MID(PART_A!F2,FIND("_attacks_",PART_A!F2)+9,LEN(PART_A!F2)))&"). ","") -> att(a,b).
A3: ="p"&PART_A!A3&"_version"&PART_A!C3 -> p1_versionG | B3: =IF(PART_A!J3="Attack","att("&LOWER(LEFT(PART_A!F3,FIND("_",PART_A!F3)-1))&","&LOWER(MID(PART_A!F3,FIND("_attacks_",PART_A!F3)+9,LEN(PART_A!F3)))&"). ","")
A4: ="p"&PART_A!A4&"_version"&PART_A!C4 -> p1_versionG | B4: =IF(PART_A!J4="Attack","att("&LOWER(LEFT(PART_A!F4,FIND("_",PART_A!F4)-1))&","&LOWER(MID(PART_A!F4,FIND("_attacks_",PART_A!F4)+9,LEN(PART_A!F4)))&"). ","")
A5: ="p"&PART_A!A5&"_version"&PART_A!C5 -> p1_versionG | B5: =IF(PART_A!J5="Attack","att("&LOWER(LEFT(PART_A!F5,FIND("_",PART_A!F5)-1))&","&LOWER(MID(PART_A!F5,FIND("_attacks_",PART_A!F5)+9,LEN(PART_A!F5)))&"). ","")
A6: ="p"&PART_A!A6&"_version"&PART_A!C6 -> p1_versionG | B6: =IF(PART_A!J6="Attack","att("&LOWER(LEFT(PART_A!F6,FIND("_",PART_A!F6)-1))&","&LOWER(MID(PART_A!F6,FIND("_attacks_",PART_A!F6)+9,LEN(PART_A!F6)))&"). ","") -> att(b,a).
A7: ="p"&PART_A!A7&"_version"&PART_A!C7 -> p1_versionG | B7: =IF(PART_A!J7="Attack","att("&LOWER(LEFT(PART_A!F7,FIND("_",PART_A!F7)-1))&","&LOWER(MID(PART_A!F7,FIND("_attacks_",PART_A!F7)+9,LEN(PART_A!F7)))&"). ","")
A8: ="p"&PART_A!A8&"_version"&PART_A!C8 -> p1_versionG | B8: =IF(PART_A!J8="Attack","att("&LOWER(LEFT(PART_A!F8,FIND("_",PART_A!F8)-1))&","&LOWER(MID(PART_A!F8,FIND("_attacks_",PART_A!F8)+9,LEN(PART_A!F8)))&"). ","")
A9: ="p"&PART_A!A9&"_version"&PART_A!C9 -> p1_versionG | B9: =IF(PART_A!J9="Attack","att("&LOWER(LEFT(PART_A!F9,FIND("_",PART_A!F9)-1))&","&LOWER(MID(PART_A!F9,FIND("_attacks_",PART_A!F9)+9,LEN(PART_A!F9)))&"). ","")
A10: ="p"&PART_A!A10&"_version"&PART_A!C10 -> p1_versionG | B10: =IF(PART_A!J10="Attack","att("&LOWER(LEFT(PART_A!F10,FIND("_",PART_A!F10)-1))&","&LOWER(MID(PART_A!F10,FIND("_attacks_",PART_A!F10)+9,LEN(PART_A!F10)))&"). ","")
A11: ="p"&PART_A!A11&"_version"&PART_A!C11 -> p1_versionG | B11: =IF(PART_A!J11="Attack","att("&LOWER(LEFT(PART_A!F11,FIND("_",PART_A!F11)-1))&","&LOWER(MID(PART_A!F11,FIND("_attacks_",PART_A!F11)+9,LEN(PART_A!F11)))&"). ","") -> att(c,b).
A12: ="p"&PART_A!A12&"_version"&PART_A!C12 -> p1_versionG | B12: =IF(PART_A!J12="Attack","att("&LOWER(LEFT(PART_A!F12,FIND("_",PART_A!F12)-1))&","&LOWER(MID(PART_A!F12,FIND("_attacks_",PART_A!F12)+9,LEN(PART_A!F12)))&"). ","")
A13: ="p"&PART_A!A13&"_version"&PART_A!C13 -> p1_versionG | B13: =IF(PART_A!J13="Attack","att("&LOWER(LEFT(PART_A!F13,FIND("_",PART_A!F13)-1))&","&LOWER(MID(PART_A!F13,FIND("_attacks_",PART_A!F13)+9,LEN(PART_A!F13)))&"). ","") -> att(c,e).
... A1491: ="p"&PART_A!A1491&"_version"&PART_A!C1491 -> p130_versionG | B1491: =IF(PART_A!J1491="Attack","att("&LOWER(LEFT(PART_A!F1491,FIND("_",PART_A!F1491)-1))&","&LOWER(MID(PART_A!F1491,FIND("_attacks_",PART_A!F1491)+9,LEN(PART_A!F1491)))&"). ","")

Sheet Labellings
A1: ID | B1: version | C1: arg | D1: EXTENSION | E1: NEGATIVE
A2: ="p"&PART_B!A258&"_version"&PART_B!C258 -> p75_versionA | B2: =RIGHT(A2,1) -> A | C2: =LOWER(PART_B!F258) -> a | D2: =IF(PART_B!N258="Accept","in",IF(PART_B!N258="Reject","out","undec")) -> in | E2: =IF(PART_B!N258="Accept",CHOOSE(RANDBETWEEN(1,2),"undec","out"),IF(PART_B!N258="Reject",CHOOSE(RANDBETWEEN(1,2),"in","undec"),CHOOSE(RANDBETWEEN(1,2),"in","out"))) -> undec
A3: ="p"&PART_B!A259&"_version"&PART_B!C259 -> p75_versionA | B3: =RIGHT(A3,1) -> A | C3: =LOWER(PART_B!F259) -> b | D3: =IF(PART_B!N259="Accept","in",IF(PART_B!N259="Reject","out","undec")) -> out | E3: =IF(PART_B!N259="Accept",CHOOSE(RANDBETWEEN(1,2),"undec","out"),IF(PART_B!N259="Reject",CHOOSE(RANDBETWEEN(1,2),"in","undec"),CHOOSE(RANDBETWEEN(1,2),"in","out"))) -> in
A4: ="p"&PART_B!A260&"_version"&PART_B!C260 -> p75_versionA | B4: =RIGHT(A4,1) -> A | C4: =LOWER(PART_B!F260) -> c | D4: =IF(PART_B!N260="Accept","in",IF(PART_B!N260="Reject","out","undec")) -> undec | E4: =IF(PART_B!N260="Accept",CHOOSE(RANDBETWEEN(1,2),"undec","out"),IF(PART_B!N260="Reject",CHOOSE(RANDBETWEEN(1,2),"in","undec"),CHOOSE(RANDBETWEEN(1,2),"in","out"))) -> in
A5: ="p"&PART_B!A261&"_version"&PART_B!C261 -> p75_versionA | B5: =RIGHT(A5,1) -> A | C5: =LOWER(PART_B!F261) -> d | D5: =IF(PART_B!N261="Accept","in",IF(PART_B!N261="Reject","out","undec")) -> undec | E5: =IF(PART_B!N261="Accept",CHOOSE(RANDBETWEEN(1,2),"undec","out"),IF(PART_B!N261="Reject",CHOOSE(RANDBETWEEN(1,2),"in","undec"),CHOOSE(RANDBETWEEN(1,2),"in","out"))) -> out
A6: ="p"&PART_B!A262&"_version"&PART_B!C262 -> p76_versionA | B6: =RIGHT(A6,1) -> A | C6: =LOWER(PART_B!F262) -> a | D6: =IF(PART_B!N262="Accept","in",IF(PART_B!N262="Reject","out","undec")) -> in | E6: =IF(PART_B!N262="Accept",CHOOSE(RANDBETWEEN(1,2),"undec","out"),IF(PART_B!N262="Reject",CHOOSE(RANDBETWEEN(1,2),"in","undec"),CHOOSE(RANDBETWEEN(1,2),"in","out"))) -> out
A7: ="p"&PART_B!A263&"_version"&PART_B!C263 -> p76_versionA | B7: =RIGHT(A7,1) -> A | C7: =LOWER(PART_B!F263) -> b | D7: =IF(PART_B!N263="Accept","in",IF(PART_B!N263="Reject","out","undec")) -> out | E7: =IF(PART_B!N263="Accept",CHOOSE(RANDBETWEEN(1,2),"undec","out"),IF(PART_B!N263="Reject",CHOOSE(RANDBETWEEN(1,2),"in","undec"),CHOOSE(RANDBETWEEN(1,2),"in","out"))) -> undec
A8: ="p"&PART_B!A264&"_version"&PART_B!C264 -> p76_versionA | B8: =RIGHT(A8,1) -> A | C8: =LOWER(PART_B!F264) -> c | D8: =IF(PART_B!N264="Accept","in",IF(PART_B!N264="Reject","out","undec")) -> undec | E8: =IF(PART_B!N264="Accept",CHOOSE(RANDBETWEEN(1,2),"undec","out"),IF(PART_B!N264="Reject",CHOOSE(RANDBETWEEN(1,2),"in","undec"),CHOOSE(RANDBETWEEN(1,2),"in","out"))) -> out
A9: ="p"&PART_B!A265&"_version"&PART_B!C265 -> p76_versionA | B9: =RIGHT(A9,1) -> A | C9: =LOWER(PART_B!F265) -> d | D9: =IF(PART_B!N265="Accept","in",IF(PART_B!N265="Reject","out","undec")) -> undec | E9: =IF(PART_B!N265="Accept",CHOOSE(RANDBETWEEN(1,2),"undec","out"),IF(PART_B!N265="Reject",CHOOSE(RANDBETWEEN(1,2),"in","undec"),CHOOSE(RANDBETWEEN(1,2),"in","out"))) -> in
A10: ="p"&PART_B!A266&"_version"&PART_B!C266 -> p77_versionA | B10: =RIGHT(A10,1) -> A | C10: =LOWER(PART_B!F266) -> a | D10: =IF(PART_B!N266="Accept","in",IF(PART_B!N266="Reject","out","undec")) -> undec | E10: =IF(PART_B!N266="Accept",CHOOSE(RANDBETWEEN(1,2),"undec","out"),IF(PART_B!N266="Reject",CHOOSE(RANDBETWEEN(1,2),"in","undec"),CHOOSE(RANDBETWEEN(1,2),"in","out"))) -> out
A11: ="p"&PART_B!A267&"_version"&PART_B!C267 -> p77_versionA | B11: =RIGHT(A11,1) -> A | C11: =LOWER(PART_B!F267) -> b | D11: =IF(PART_B!N267="Accept","in",IF(PART_B!N267="Reject","out","undec")) -> out | E11: =IF(PART_B!N267="Accept",CHOOSE(RANDBETWEEN(1,2),"undec","out"),IF(PART_B!N267="Reject",CHOOSE(RANDBETWEEN(1,2),"in","undec"),CHOOSE(RANDBETWEEN(1,2),"in","out"))) -> in
A12: ="p"&PART_B!A268&"_version"&PART_B!C268 -> p77_versionA | B12: =RIGHT(A12,1) -> A | C12: =LOWER(PART_B!F268) -> c | D12: =IF(PART_B!N268="Accept","in",IF(PART_B!N268="Reject","out","undec")) -> in | E12: =IF(PART_B!N268="Accept",CHOOSE(RANDBETWEEN(1,2),"undec","out"),IF(PART_B!N268="Reject",CHOOSE(RANDBETWEEN(1,2),"in","undec"),CHOOSE(RANDBETWEEN(1,2),"in","out"))) -> undec
A13: ="p"&PART_B!A269&"_version"&PART_B!C269 -> p77_versionA | B13: =RIGHT(A13,1) -> A | C13: =LOWER(PART_B!F269) -> d | D13: =IF(PART_B!N269="Accept","in",IF(PART_B!N269="Reject","out","undec")) -> in | E13: =IF(PART_B!N269="Accept",CHOOSE(RANDBETWEEN(1,2),"undec","out"),IF(PART_B!N269="Reject",CHOOSE(RANDBETWEEN(1,2),"in","undec"),CHOOSE(RANDBETWEEN(1,2),"in","out"))) -> out
... A81: ="p"&PART_B!A337&"_version"&PART_B!C337 -> p94_versionA | B81: =RIGHT(A81,1) -> A | C81: =LOWER(PART_B!F337) -> d | D81: =IF(PART_B!N337="Accept","in",IF(PART_B!N337="Reject","out","undec")) -> in | E81: =IF(PART_B!N337="Accept",CHOOSE(RANDBETWEEN(1,2),"undec","out"),IF(PART_B!N337="Reject",CHOOSE(RANDBETWEEN(1,2),"in","undec"),CHOOSE(RANDBETWEEN(1,2),"in","out"))) -> out
A82: ="p"&PART_B!A358&"_version"&PART_B!C358 -> p100_versionB | B82: =RIGHT(A82,1) -> B | C82: =LOWER(PART_B!F358) -> a | D82: =IF(PART_B!N358="Accept","in",IF(PART_B!N358="Reject","out","undec")) -> in | E82: =IF(PART_B!N358="Accept",CHOOSE(RANDBETWEEN(1,2),"undec","out"),IF(PART_B!N358="Reject",CHOOSE(RANDBETWEEN(1,2),"in","undec"),CHOOSE(RANDBETWEEN(1,2),"in","out"))) -> undec
A83: ="p"&PART_B!A359&"_version"&PART_B!C359 -> p100_versionB | B83: =RIGHT(A83,1) -> B | C83: =LOWER(PART_B!F359) -> b | D83: =IF(PART_B!N359="Accept","in",IF(PART_B!N359="Reject","out","undec")) -> out | E83: =IF(PART_B!N359="Accept",CHOOSE(RANDBETWEEN(1,2),"undec","out"),IF(PART_B!N359="Reject",CHOOSE(RANDBETWEEN(1,2),"in","undec"),CHOOSE(RANDBETWEEN(1,2),"in","out"))) -> undec
A84: ="p"&PART_B!A360&"_version"&PART_B!C360 -> p100_versionB | B84: =RIGHT(A84,1) -> B | C84: =LOWER(PART_B!F360) -> c | D84: =IF(PART_B!N360="Accept","in",IF(PART_B!N360="Reject","out","undec")) -> undec | E84: =IF(PART_B!N360="Accept",CHOOSE(RANDBETWEEN(1,2),"undec","out"),IF(PART_B!N360="Reject",CHOOSE(RANDBETWEEN(1,2),"in","undec"),CHOOSE(RANDBETWEEN(1,2),"in","out"))) -> out
A85: ="p"&PART_B!A361&"_version"&PART_B!C361 -> p100_versionB | B85: =RIGHT(A85,1) -> B | C85: =LOWER(PART_B!F361) -> d | D85: =IF(PART_B!N361="Accept","in",IF(PART_B!N361="Reject","out","undec")) -> undec | E85: =IF(PART_B!N361="Accept",CHOOSE(RANDBETWEEN(1,2),"undec","out"),IF(PART_B!N361="Reject",CHOOSE(RANDBETWEEN(1,2),"in","undec"),CHOOSE(RANDBETWEEN(1,2),"in","out"))) -> in
A86: ="p"&PART_B!A362&"_version"&PART_B!C362 -> p101_versionB | B86: =RIGHT(A86,1) -> B | C86: =LOWER(PART_B!F362) -> a | D86: =IF(PART_B!N362="Accept","in",IF(PART_B!N362="Reject","out","undec")) -> in | E86: =IF(PART_B!N362="Accept",CHOOSE(RANDBETWEEN(1,2),"undec","out"),IF(PART_B!N362="Reject",CHOOSE(RANDBETWEEN(1,2),"in","undec"),CHOOSE(RANDBETWEEN(1,2),"in","out"))) -> undec
A87: ="p"&PART_B!A363&"_version"&PART_B!C363 -> p101_versionB | B87: =RIGHT(A87,1) -> B | C87: =LOWER(PART_B!F363) -> b | D87: =IF(PART_B!N363="Accept","in",IF(PART_B!N363="Reject","out","undec")) -> out | E87: =IF(PART_B!N363="Accept",CHOOSE(RANDBETWEEN(1,2),"undec","out"),IF(PART_B!N363="Reject",CHOOSE(RANDBETWEEN(1,2),"in","undec"),CHOOSE(RANDBETWEEN(1,2),"in","out"))) -> in
A88: ="p"&PART_B!A364&"_version"&PART_B!C364 -> p101_versionB | B88: =RIGHT(A88,1) -> B | C88: =LOWER(PART_B!F364) -> c | D88: =IF(PART_B!N364="Accept","in",IF(PART_B!N364="Reject","out","undec")) -> undec | E88: =IF(PART_B!N364="Accept",CHOOSE(RANDBETWEEN(1,2),"undec","out"),IF(PART_B!N364="Reject",CHOOSE(RANDBETWEEN(1,2),"in","undec"),CHOOSE(RANDBETWEEN(1,2),"in","out"))) -> in
A89: ="p"&PART_B!A365&"_version"&PART_B!C365 -> p101_versionB | B89: =RIGHT(A89,1) -> B | C89: =LOWER(PART_B!F365) -> d | D89: =IF(PART_B!N365="Accept","in",IF(PART_B!N365="Reject","out","undec")) -> undec | E89: =IF(PART_B!N365="Accept",CHOOSE(RANDBETWEEN(1,2),"undec","out"),IF(PART_B!N365="Reject",CHOOSE(RANDBETWEEN(1,2),"in","undec"),CHOOSE(RANDBETWEEN(1,2),"in","out"))) -> out
A90: ="p"&PART_B!A366&"_version"&PART_B!C366 -> p102_versionB | B90: =RIGHT(A90,1) -> B | C90: =LOWER(PART_B!F366) -> a | D90: =IF(PART_B!N366="Accept","in",IF(PART_B!N366="Reject","out","undec")) -> out | E90: =IF(PART_B!N366="Accept",CHOOSE(RANDBETWEEN(1,2),"undec","out"),IF(PART_B!N366="Reject",CHOOSE(RANDBETWEEN(1,2),"in","undec"),CHOOSE(RANDBETWEEN(1,2),"in","out"))) -> undec
A91: ="p"&PART_B!A367&"_version"&PART_B!C367 -> p102_versionB | B91: =RIGHT(A91,1) -> B | C91: =LOWER(PART_B!F367) -> b | D91: =IF(PART_B!N367="Accept","in",IF(PART_B!N367="Reject","out","undec")) -> out | E91: =IF(PART_B!N367="Accept",CHOOSE(RANDBETWEEN(1,2),"undec","out"),IF(PART_B!N367="Reject",CHOOSE(RANDBETWEEN(1,2),"in","undec"),CHOOSE(RANDBETWEEN(1,2),"in","out"))) -> undec
A92: ="p"&PART_B!A368&"_version"&PART_B!C368 -> p102_versionB | B92: =RIGHT(A92,1) -> B | C92: =LOWER(PART_B!F368) -> c | D92: =IF(PART_B!N368="Accept","in",IF(PART_B!N368="Reject","out","undec")) -> undec | E92: =IF(PART_B!N368="Accept",CHOOSE(RANDBETWEEN(1,2),"undec","out"),IF(PART_B!N368="Reject",CHOOSE(RANDBETWEEN(1,2),"in","undec"),CHOOSE(RANDBETWEEN(1,2),"in","out"))) -> in
A93: ="p"&PART_B!A369&"_version"&PART_B!C369 -> p102_versionB | B93: =RIGHT(A93,1) -> B | C93: =LOWER(PART_B!F369) -> d | D93: =IF(PART_B!N369="Accept","in",IF(PART_B!N369="Reject","out","undec")) -> undec | E93: =IF(PART_B!N369="Accept",CHOOSE(RANDBETWEEN(1,2),"undec","out"),IF(PART_B!N369="Reject",CHOOSE(RANDBETWEEN(1,2),"in","undec"),CHOOSE(RANDBETWEEN(1,2),"in","out"))) -> in
... A125: ="p"&PART_B!A401&"_version"&PART_B!C401 -> p110_versionB | B125: =RIGHT(A125,1) -> B | C125: =LOWER(PART_B!F401) -> d | D125: =IF(PART_B!N401="Accept","in",IF(PART_B!N401="Reject","out","undec")) -> undec | E125: =IF(PART_B!N401="Accept",CHOOSE(RANDBETWEEN(1,2),"undec","out"),IF(PART_B!N401="Reject",CHOOSE(RANDBETWEEN(1,2),"in","undec"),CHOOSE(RANDBETWEEN(1,2),"in","out"))) -> out
A126: ="p"&PART_B!A63&"_version"&PART_B!C63 -> p18_versionB | B126: =RIGHT(A126,1) -> B | C126: =LOWER(PART_B!F63) -> a | D126: =IF(PART_B!N63="Accept","in",IF(PART_B!N63="Reject","out","undec")) -> in | E126: =IF(PART_B!N63="Accept",CHOOSE(RANDBETWEEN(1,2),"undec","out"),IF(PART_B!N63="Reject",CHOOSE(RANDBETWEEN(1,2),"in","undec"),CHOOSE(RANDBETWEEN(1,2),"in","out"))) -> undec
A127: ="p"&PART_B!A64&"_version"&PART_B!C64 -> p18_versionB | B127: =RIGHT(A127,1) -> B | C127: =LOWER(PART_B!F64) -> b | D127: =IF(PART_B!N64="Accept","in",IF(PART_B!N64="Reject","out","undec")) -> out | E127: =IF(PART_B!N64="Accept",CHOOSE(RANDBETWEEN(1,2),"undec","out"),IF(PART_B!N64="Reject",CHOOSE(RANDBETWEEN(1,2),"in","undec"),CHOOSE(RANDBETWEEN(1,2),"in","out"))) -> in
A128: ="p"&PART_B!A65&"_version"&PART_B!C65 -> p18_versionB | B128: =RIGHT(A128,1) -> B | C128: =LOWER(PART_B!F65) -> c | D128: =IF(PART_B!N65="Accept","in",IF(PART_B!N65="Reject","out","undec")) -> undec | E128: =IF(PART_B!N65="Accept",CHOOSE(RANDBETWEEN(1,2),"undec","out"),IF(PART_B!N65="Reject",CHOOSE(RANDBETWEEN(1,2),"in","undec"),CHOOSE(RANDBETWEEN(1,2),"in","out"))) -> out
A129: ="p"&PART_B!A66&"_version"&PART_B!C66 -> p18_versionB | B129: =RIGHT(A129,1) -> B | C129: =LOWER(PART_B!F66) -> d | D129: =IF(PART_B!N66="Accept","in",IF(PART_B!N66="Reject","out","undec")) -> undec | E129: =IF(PART_B!N66="Accept",CHOOSE(RANDBETWEEN(1,2),"undec","out"),IF(PART_B!N66="Reject",CHOOSE(RANDBETWEEN(1,2),"in","undec"),CHOOSE(RANDBETWEEN(1,2),"in","out"))) -> in
A130: ="p"&PART_B!A67&"_version"&PART_B!C67 -> p19_versionB | B130: =RIGHT(A130,1) -> B | C130: =LOWER(PART_B!F67) -> a | D130: =IF(PART_B!N67="Accept","in",IF(PART_B!N67="Reject","out","undec")) -> in | E130: =IF(PART_B!N67="Accept",CHOOSE(RANDBETWEEN(1,2),"undec","out"),IF(PART_B!N67="Reject",CHOOSE(RANDBETWEEN(1,2),"in","undec"),CHOOSE(RANDBETWEEN(1,2),"in","out"))) -> out
A131: ="p"&PART_B!A68&"_version"&PART_B!C68 -> p19_versionB | B131: =RIGHT(A131,1) -> B | C131: =LOWER(PART_B!F68) -> b | D131: =IF(PART_B!N68="Accept","in",IF(PART_B!N68="Reject","out","undec")) -> out | E131: =IF(PART_B!N68="Accept",CHOOSE(RANDBETWEEN(1,2),"undec","out"),IF(PART_B!N68="Reject",CHOOSE(RANDBETWEEN(1,2),"in","undec"),CHOOSE(RANDBETWEEN(1,2),"in","out"))) -> in
A132: ="p"&PART_B!A69&"_version"&PART_B!C69 -> p19_versionB | B132: =RIGHT(A132,1) -> B | C132: =LOWER(PART_B!F69) -> c | D132: =IF(PART_B!N69="Accept","in",IF(PART_B!N69="Reject","out","undec")) -> undec | E132: =IF(PART_B!N69="Accept",CHOOSE(RANDBETWEEN(1,2),"undec","out"),IF(PART_B!N69="Reject",CHOOSE(RANDBETWEEN(1,2),"in","undec"),CHOOSE(RANDBETWEEN(1,2),"in","out"))) -> out
A133: ="p"&PART_B!A70&"_version"&PART_B!C70 -> p19_versionB | B133: =RIGHT(A133,1) -> B | C133: =LOWER(PART_B!F70) -> d | D133: =IF(PART_B!N70="Accept","in",IF(PART_B!N70="Reject","out","undec")) -> undec | E133: =IF(PART_B!N70="Accept",CHOOSE(RANDBETWEEN(1,2),"undec","out"),IF(PART_B!N70="Reject",CHOOSE(RANDBETWEEN(1,2),"in","undec"),CHOOSE(RANDBETWEEN(1,2),"in","out"))) -> in
A134: ="p"&PART_B!A71&"_version"&PART_B!C71 -> p20_versionB | B134: =RIGHT(A134,1) -> B | C134: =LOWER(PART_B!F71) -> a | D134: =IF(PART_B!N71="Accept","in",IF(PART_B!N71="Reject","out","undec")) -> in | E134: =IF(PART_B!N71="Accept",CHOOSE(RANDBETWEEN(1,2),"undec","out"),IF(PART_B!N71="Reject",CHOOSE(RANDBETWEEN(1,2),"in","undec"),CHOOSE(RANDBETWEEN(1,2),"in","out"))) -> undec
A135: ="p"&PART_B!A72&"_version"&PART_B!C72 -> p20_versionB | B135: =RIGHT(A135,1) -> B | C135: =LOWER(PART_B!F72) -> b | D135: =IF(PART_B!N72="Accept","in",IF(PART_B!N72="Reject","out","undec")) -> out | E135: =IF(PART_B!N72="Accept",CHOOSE(RANDBETWEEN(1,2),"undec","out"),IF(PART_B!N72="Reject",CHOOSE(RANDBETWEEN(1,2),"in","undec"),CHOOSE(RANDBETWEEN(1,2),"in","out"))) -> in
A136: ="p"&PART_B!A73&"_version"&PART_B!C73 -> p20_versionB | B136: =RIGHT(A136,1) -> B | C136: =LOWER(PART_B!F73) -> c | D136: =IF(PART_B!N73="Accept","in",IF(PART_B!N73="Reject","out","undec")) -> out | E136: =IF(PART_B!N73="Accept",CHOOSE(RANDBETWEEN(1,2),"undec","out"),IF(PART_B!N73="Reject",CHOOSE(RANDBETWEEN(1,2),"in","undec"),CHOOSE(RANDBETWEEN(1,2),"in","out"))) -> undec
A137: ="p"&PART_B!A74&"_version"&PART_B!C74 -> p20_versionB | B137: =RIGHT(A137,1) -> B | C137: =LOWER(PART_B!F74) -> d | D137: =IF(PART_B!N74="Accept","in",IF(PART_B!N74="Reject","out","undec")) -> in | E137: =IF(PART_B!N74="Accept",CHOOSE(RANDBETWEEN(1,2),"undec","out"),IF(PART_B!N74="Reject",CHOOSE(RANDBETWEEN(1,2),"in","undec"),CHOOSE(RANDBETWEEN(1,2),"in","out"))) -> undec
... A141: ="p"&PART_B!A78&"_version"&PART_B!C78 -> p21_versionB | B141: =RIGHT(A141,1) -> B | C141: =LOWER(PART_B!F78) -> d | D141: =IF(PART_B!N78="Accept","in",IF(PART_B!N78="Reject","out","undec")) -> undec | E141: =IF(PART_B!N78="Accept",CHOOSE(RANDBETWEEN(1,2),"undec","out"),IF(PART_B!N78="Reject",CHOOSE(RANDBETWEEN(1,2),"in","undec"),CHOOSE(RANDBETWEEN(1,2),"in","out"))) -> in
...
